Workbook

Sheet Export_ControlTot
A1: ;YEAR | B1: BYU | C1: ENSIGN | D1: SLCC_MAIN | E1: SLCC_JD | F1: SLCC_ML | G1: SLCC_SC | H1: UOFU_Main | I1: UVU_Main | J1: UVU_Lehi | K1: UVU_Payson | L1: UVU_Vineyard | M1: WSU_Main | N1: WSU_Davis | O1: WESTMIN | Q1: ABB | R1: NAME | S1: IPEDS ID
A2: 1990 | B2: =INDEX('Campus Enrol Disaggregation'!$P$5:$AC$75,MATCH(Export_ControlTot!$A2,'Campus Enrol Disaggregation'!$O$5:$O$75,0),MATCH(B$1,'Campus Enrol Disaggregation'!$P$4:$AC$4,0)) -> 30450 | C2: =INDEX('Campus Enrol Disaggregation'!$P$5:$AC$75,MATCH(Export_ControlTot!$A2,'Campus Enrol Disaggregation'!$O$5:$O$75,0),MATCH(C$1,'Campus Enrol Disaggregation'!$P$4:$AC$4,0)) -> 0 | D2: =INDEX('Campus Enrol Disaggregation'!$P$5:$AC$75,MATCH(Export_ControlTot!$A2,'Campus Enrol Disaggregation'!$O$5:$O$75,0),MATCH(D$1,'Campus Enrol Disaggregation'!$P$4:$AC$4,0)) -> 9150 | E2: =INDEX('Campus Enrol Disaggregation'!$P$5:$AC$75,MATCH(Export_ControlTot!$A2,'Campus Enrol Disaggregation'!$O$5:$O$75,0),MATCH(E$1,'Campus Enrol Disaggregation'!$P$4:$AC$4,0)) -> 1800 | F2: =INDEX('Campus Enrol Disaggregation'!$P$5:$AC$75,MATCH(Export_ControlTot!$A2,'Campus Enrol Disaggregation'!$O$5:$O$75,0),MATCH(F$1,'Campus Enrol Disaggregation'!$P$4:$AC$4,0)) -> 200 | G2: =INDEX('Campus Enrol Disaggregation'!$P$5:$AC$75,MATCH(Export_ControlTot!$A2,'Campus Enrol Disaggregation'!$O$5:$O$75,0),MATCH(G$1,'Campus Enrol Disaggregation'!$P$4:$AC$4,0)) -> 1350 | H2: =INDEX('Campus Enrol Disaggregation'!$P$5:$AC$75,MATCH(Export_ControlTot!$A2,'Campus Enrol Disaggregation'!$O$5:$O$75,0),MATCH(H$1,'Campus Enrol Disaggregation'!$P$4:$AC$4,0)) -> 23550 | I2: =INDEX('Campus Enrol Disaggregation'!$P$5:$AC$75,MATCH(Export_ControlTot!$A2,'Campus Enrol Disaggregation'!$O$5:$O$75,0),MATCH(I$1,'Campus Enrol Disaggregation'!$P$4:$AC$4,0)) -> 7900 | ... O2: =INDEX('Campus Enrol Disaggregation'!$P$5:$AC$75,MATCH(Export_ControlTot!$A2,'Campus Enrol Disaggregation'!$O$5:$O$75,0),MATCH(O$1,'Campus Enrol Disaggregation'!$P$4:$AC$4,0)) -> 0 | Q2: BYU | R2: Brigham Young University | S2: 230038
A3: 1991 | B3: =INDEX('Campus Enrol Disaggregation'!$P$5:$AC$75,MATCH(Export_ControlTot!$A3,'Campus Enrol Disaggregation'!$O$5:$O$75,0),MATCH(B$1,'Campus Enrol Disaggregation'!$P$4:$AC$4,0)) -> 31100 | C3: =INDEX('Campus Enrol Disaggregation'!$P$5:$AC$75,MATCH(Export_ControlTot!$A3,'Campus Enrol Disaggregation'!$O$5:$O$75,0),MATCH(C$1,'Campus Enrol Disaggregation'!$P$4:$AC$4,0)) -> 0 | D3: =INDEX('Campus Enrol Disaggregation'!$P$5:$AC$75,MATCH(Export_ControlTot!$A3,'Campus Enrol Disaggregation'!$O$5:$O$75,0),MATCH(D$1,'Campus Enrol Disaggregation'!$P$4:$AC$4,0)) -> 10950 | E3: =INDEX('Campus Enrol Disaggregation'!$P$5:$AC$75,MATCH(Export_ControlTot!$A3,'Campus Enrol Disaggregation'!$O$5:$O$75,0),MATCH(E$1,'Campus Enrol Disaggregation'!$P$4:$AC$4,0)) -> 2150 | F3: =INDEX('Campus Enrol Disaggregation'!$P$5:$AC$75,MATCH(Export_ControlTot!$A3,'Campus Enrol Disaggregation'!$O$5:$O$75,0),MATCH(F$1,'Campus Enrol Disaggregation'!$P$4:$AC$4,0)) -> 250 | G3: =INDEX('Campus Enrol Disaggregation'!$P$5:$AC$75,MATCH(Export_ControlTot!$A3,'Campus Enrol Disaggregation'!$O$5:$O$75,0),MATCH(G$1,'Campus Enrol Disaggregation'!$P$4:$AC$4,0)) -> 1650 | H3: =INDEX('Campus Enrol Disaggregation'!$P$5:$AC$75,MATCH(Export_ControlTot!$A3,'Campus Enrol Disaggregation'!$O$5:$O$75,0),MATCH(H$1,'Campus Enrol Disaggregation'!$P$4:$AC$4,0)) -> 24750 | I3: =INDEX('Campus Enrol Disaggregation'!$P$5:$AC$75,MATCH(Export_ControlTot!$A3,'Campus Enrol Disaggregation'!$O$5:$O$75,0),MATCH(I$1,'Campus Enrol Disaggregation'!$P$4:$AC$4,0)) -> 8800 | ... O3: =INDEX('Campus Enrol Disaggregation'!$P$5:$AC$75,MATCH(Export_ControlTot!$A3,'Campus Enrol Disaggregation'!$O$5:$O$75,0),MATCH(O$1,'Campus Enrol Disaggregation'!$P$4:$AC$4,0)) -> 0 | Q3: ENSIGN | R3: Ensign College | S3: 230418
A4: 1992 | B4: =INDEX('Campus Enrol Disaggregation'!$P$5:$AC$75,MATCH(Export_ControlTot!$A4,'Campus Enrol Disaggregation'!$O$5:$O$75,0),MATCH(B$1,'Campus Enrol Disaggregation'!$P$4:$AC$4,0)) -> 31100 | C4: =INDEX('Campus Enrol Disaggregation'!$P$5:$AC$75,MATCH(Export_ControlTot!$A4,'Campus Enrol Disaggregation'!$O$5:$O$75,0),MATCH(C$1,'Campus Enrol Disaggregation'!$P$4:$AC$4,0)) -> 0 | D4: =INDEX('Campus Enrol Disaggregation'!$P$5:$AC$75,MATCH(Export_ControlTot!$A4,'Campus Enrol Disaggregation'!$O$5:$O$75,0),MATCH(D$1,'Campus Enrol Disaggregation'!$P$4:$AC$4,0)) -> 12150 | E4: =INDEX('Campus Enrol Disaggregation'!$P$5:$AC$75,MATCH(Export_ControlTot!$A4,'Campus Enrol Disaggregation'!$O$5:$O$75,0),MATCH(E$1,'Campus Enrol Disaggregation'!$P$4:$AC$4,0)) -> 2350 | F4: =INDEX('Campus Enrol Disaggregation'!$P$5:$AC$75,MATCH(Export_ControlTot!$A4,'Campus Enrol Disaggregation'!$O$5:$O$75,0),MATCH(F$1,'Campus Enrol Disaggregation'!$P$4:$AC$4,0)) -> 300 | G4: =INDEX('Campus Enrol Disaggregation'!$P$5:$AC$75,MATCH(Export_ControlTot!$A4,'Campus Enrol Disaggregation'!$O$5:$O$75,0),MATCH(G$1,'Campus Enrol Disaggregation'!$P$4:$AC$4,0)) -> 1800 | H4: =INDEX('Campus Enrol Disaggregation'!$P$5:$AC$75,MATCH(Export_ControlTot!$A4,'Campus Enrol Disaggregation'!$O$5:$O$75,0),MATCH(H$1,'Campus Enrol Disaggregation'!$P$4:$AC$4,0)) -> 25050 | I4: =INDEX('Campus Enrol Disaggregation'!$P$5:$AC$75,MATCH(Export_ControlTot!$A4,'Campus Enrol Disaggregation'!$O$5:$O$75,0),MATCH(I$1,'Campus Enrol Disaggregation'!$P$4:$AC$4,0)) -> 9600 | ... O4: =INDEX('Campus Enrol Disaggregation'!$P$5:$AC$75,MATCH(Export_ControlTot!$A4,'Campus Enrol Disaggregation'!$O$5:$O$75,0),MATCH(O$1,'Campus Enrol Disaggregation'!$P$4:$AC$4,0)) -> 0 | Q4: SLCC | R4: Salt Lake Community College | S4: 230746
A5: 1993 | B5: =INDEX('Campus Enrol Disaggregation'!$P$5:$AC$75,MATCH(Export_ControlTot!$A5,'Campus Enrol Disaggregation'!$O$5:$O$75,0),MATCH(B$1,'Campus Enrol Disaggregation'!$P$4:$AC$4,0)) -> 30550 | C5: =INDEX('Campus Enrol Disaggregation'!$P$5:$AC$75,MATCH(Export_ControlTot!$A5,'Campus Enrol Disaggregation'!$O$5:$O$75,0),MATCH(C$1,'Campus Enrol Disaggregation'!$P$4:$AC$4,0)) -> 0 | D5: =INDEX('Campus Enrol Disaggregation'!$P$5:$AC$75,MATCH(Export_ControlTot!$A5,'Campus Enrol Disaggregation'!$O$5:$O$75,0),MATCH(D$1,'Campus Enrol Disaggregation'!$P$4:$AC$4,0)) -> 12550 | E5: =INDEX('Campus Enrol Disaggregation'!$P$5:$AC$75,MATCH(Export_ControlTot!$A5,'Campus Enrol Disaggregation'!$O$5:$O$75,0),MATCH(E$1,'Campus Enrol Disaggregation'!$P$4:$AC$4,0)) -> 2450 | F5: =INDEX('Campus Enrol Disaggregation'!$P$5:$AC$75,MATCH(Export_ControlTot!$A5,'Campus Enrol Disaggregation'!$O$5:$O$75,0),MATCH(F$1,'Campus Enrol Disaggregation'!$P$4:$AC$4,0)) -> 300 | G5: =INDEX('Campus Enrol Disaggregation'!$P$5:$AC$75,MATCH(Export_ControlTot!$A5,'Campus Enrol Disaggregation'!$O$5:$O$75,0),MATCH(G$1,'Campus Enrol Disaggregation'!$P$4:$AC$4,0)) -> 1850 | H5: =INDEX('Campus Enrol Disaggregation'!$P$5:$AC$75,MATCH(Export_ControlTot!$A5,'Campus Enrol Disaggregation'!$O$5:$O$75,0),MATCH(H$1,'Campus Enrol Disaggregation'!$P$4:$AC$4,0)) -> 25150 | I5: =INDEX('Campus Enrol Disaggregation'!$P$5:$AC$75,MATCH(Export_ControlTot!$A5,'Campus Enrol Disaggregation'!$O$5:$O$75,0),MATCH(I$1,'Campus Enrol Disaggregation'!$P$4:$AC$4,0)) -> 10500 | ... O5: =INDEX('Campus Enrol Disaggregation'!$P$5:$AC$75,MATCH(Export_ControlTot!$A5,'Campus Enrol Disaggregation'!$O$5:$O$75,0),MATCH(O$1,'Campus Enrol Disaggregation'!$P$4:$AC$4,0)) -> 0 | Q5: UofU | R5: University of Utah | S5: 230764
A6: 1994 | B6: =INDEX('Campus Enrol Disaggregation'!$P$5:$AC$75,MATCH(Export_ControlTot!$A6,'Campus Enrol Disaggregation'!$O$5:$O$75,0),MATCH(B$1,'Campus Enrol Disaggregation'!$P$4:$AC$4,0)) -> 30400 | C6: =INDEX('Campus Enrol Disaggregation'!$P$5:$AC$75,MATCH(Export_ControlTot!$A6,'Campus Enrol Disaggregation'!$O$5:$O$75,0),MATCH(C$1,'Campus Enrol Disaggregation'!$P$4:$AC$4,0)) -> 0 | D6: =INDEX('Campus Enrol Disaggregation'!$P$5:$AC$75,MATCH(Export_ControlTot!$A6,'Campus Enrol Disaggregation'!$O$5:$O$75,0),MATCH(D$1,'Campus Enrol Disaggregation'!$P$4:$AC$4,0)) -> 13300 | E6: =INDEX('Campus Enrol Disaggregation'!$P$5:$AC$75,MATCH(Export_ControlTot!$A6,'Campus Enrol Disaggregation'!$O$5:$O$75,0),MATCH(E$1,'Campus Enrol Disaggregation'!$P$4:$AC$4,0)) -> 2600 | F6: =INDEX('Campus Enrol Disaggregation'!$P$5:$AC$75,MATCH(Export_ControlTot!$A6,'Campus Enrol Disaggregation'!$O$5:$O$75,0),MATCH(F$1,'Campus Enrol Disaggregation'!$P$4:$AC$4,0)) -> 300 | G6: =INDEX('Campus Enrol Disaggregation'!$P$5:$AC$75,MATCH(Export_ControlTot!$A6,'Campus Enrol Disaggregation'!$O$5:$O$75,0),MATCH(G$1,'Campus Enrol Disaggregation'!$P$4:$AC$4,0)) -> 2000 | H6: =INDEX('Campus Enrol Disaggregation'!$P$5:$AC$75,MATCH(Export_ControlTot!$A6,'Campus Enrol Disaggregation'!$O$5:$O$75,0),MATCH(H$1,'Campus Enrol Disaggregation'!$P$4:$AC$4,0)) -> 24850 | I6: =INDEX('Campus Enrol Disaggregation'!$P$5:$AC$75,MATCH(Export_ControlTot!$A6,'Campus Enrol Disaggregation'!$O$5:$O$75,0),MATCH(I$1,'Campus Enrol Disaggregation'!$P$4:$AC$4,0)) -> 13300 | ... O6: =INDEX('Campus Enrol Disaggregation'!$P$5:$AC$75,MATCH(Export_ControlTot!$A6,'Campus Enrol Disaggregation'!$O$5:$O$75,0),MATCH(O$1,'Campus Enrol Disaggregation'!$P$4:$AC$4,0)) -> 0 | Q6: UVU | R6: Utah Valley University | S6: 230737
A7: 1995 | B7: =INDEX('Campus Enrol Disaggregation'!$P$5:$AC$75,MATCH(Export_ControlTot!$A7,'Campus Enrol Disaggregation'!$O$5:$O$75,0),MATCH(B$1,'Campus Enrol Disaggregation'!$P$4:$AC$4,0)) -> 30450 | C7: =INDEX('Campus Enrol Disaggregation'!$P$5:$AC$75,MATCH(Export_ControlTot!$A7,'Campus Enrol Disaggregation'!$O$5:$O$75,0),MATCH(C$1,'Campus Enrol Disaggregation'!$P$4:$AC$4,0)) -> 0 | D7: =INDEX('Campus Enrol Disaggregation'!$P$5:$AC$75,MATCH(Export_ControlTot!$A7,'Campus Enrol Disaggregation'!$O$5:$O$75,0),MATCH(D$1,'Campus Enrol Disaggregation'!$P$4:$AC$4,0)) -> 14250 | E7: =INDEX('Campus Enrol Disaggregation'!$P$5:$AC$75,MATCH(Export_ControlTot!$A7,'Campus Enrol Disaggregation'!$O$5:$O$75,0),MATCH(E$1,'Campus Enrol Disaggregation'!$P$4:$AC$4,0)) -> 2800 | F7: =INDEX('Campus Enrol Disaggregation'!$P$5:$AC$75,MATCH(Export_ControlTot!$A7,'Campus Enrol Disaggregation'!$O$5:$O$75,0),MATCH(F$1,'Campus Enrol Disaggregation'!$P$4:$AC$4,0)) -> 350 | G7: =INDEX('Campus Enrol Disaggregation'!$P$5:$AC$75,MATCH(Export_ControlTot!$A7,'Campus Enrol Disaggregation'!$O$5:$O$75,0),MATCH(G$1,'Campus Enrol Disaggregation'!$P$4:$AC$4,0)) -> 2100 | H7: =INDEX('Campus Enrol Disaggregation'!$P$5:$AC$75,MATCH(Export_ControlTot!$A7,'Campus Enrol Disaggregation'!$O$5:$O$75,0),MATCH(H$1,'Campus Enrol Disaggregation'!$P$4:$AC$4,0)) -> 25950 | I7: =INDEX('Campus Enrol Disaggregation'!$P$5:$AC$75,MATCH(Export_ControlTot!$A7,'Campus Enrol Disaggregation'!$O$5:$O$75,0),MATCH(I$1,'Campus Enrol Disaggregation'!$P$4:$AC$4,0)) -> 14050 | ... O7: =INDEX('Campus Enrol Disaggregation'!$P$5:$AC$75,MATCH(Export_ControlTot!$A7,'Campus Enrol Disaggregation'!$O$5:$O$75,0),MATCH(O$1,'Campus Enrol Disaggregation'!$P$4:$AC$4,0)) -> 0 | Q7: WSU | R7: Weber State University | S7: 230782
A8: 1996 | B8: =INDEX('Campus Enrol Disaggregation'!$P$5:$AC$75,MATCH(Export_ControlTot!$A8,'Campus Enrol Disaggregation'!$O$5:$O$75,0),MATCH(B$1,'Campus Enrol Disaggregation'!$P$4:$AC$4,0)) -> 30550 | C8: =INDEX('Campus Enrol Disaggregation'!$P$5:$AC$75,MATCH(Export_ControlTot!$A8,'Campus Enrol Disaggregation'!$O$5:$O$75,0),MATCH(C$1,'Campus Enrol Disaggregation'!$P$4:$AC$4,0)) -> 0 | D8: =INDEX('Campus Enrol Disaggregation'!$P$5:$AC$75,MATCH(Export_ControlTot!$A8,'Campus Enrol Disaggregation'!$O$5:$O$75,0),MATCH(D$1,'Campus Enrol Disaggregation'!$P$4:$AC$4,0)) -> 15300 | E8: =INDEX('Campus Enrol Disaggregation'!$P$5:$AC$75,MATCH(Export_ControlTot!$A8,'Campus Enrol Disaggregation'!$O$5:$O$75,0),MATCH(E$1,'Campus Enrol Disaggregation'!$P$4:$AC$4,0)) -> 3000 | F8: =INDEX('Campus Enrol Disaggregation'!$P$5:$AC$75,MATCH(Export_ControlTot!$A8,'Campus Enrol Disaggregation'!$O$5:$O$75,0),MATCH(F$1,'Campus Enrol Disaggregation'!$P$4:$AC$4,0)) -> 350 | G8: =INDEX('Campus Enrol Disaggregation'!$P$5:$AC$75,MATCH(Export_ControlTot!$A8,'Campus Enrol Disaggregation'!$O$5:$O$75,0),MATCH(G$1,'Campus Enrol Disaggregation'!$P$4:$AC$4,0)) -> 2300 | H8: =INDEX('Campus Enrol Disaggregation'!$P$5:$AC$75,MATCH(Export_ControlTot!$A8,'Campus Enrol Disaggregation'!$O$5:$O$75,0),MATCH(H$1,'Campus Enrol Disaggregation'!$P$4:$AC$4,0)) -> 25250 | I8: =INDEX('Campus Enrol Disaggregation'!$P$5:$AC$75,MATCH(Export_ControlTot!$A8,'Campus Enrol Disaggregation'!$O$5:$O$75,0),MATCH(I$1,'Campus Enrol Disaggregation'!$P$4:$AC$4,0)) -> 14750 | ... O8: =INDEX('Campus Enrol Disaggregation'!$P$5:$AC$75,MATCH(Export_ControlTot!$A8,'Campus Enrol Disaggregation'!$O$5:$O$75,0),MATCH(O$1,'Campus Enrol Disaggregation'!$P$4:$AC$4,0)) -> 0 | Q8: WESTMIN | R8: Westminster College | S8: 230807
A9: 1997 | B9: =INDEX('Campus Enrol Disaggregation'!$P$5:$AC$75,MATCH(Export_ControlTot!$A9,'Campus Enrol Disaggregation'!$O$5:$O$75,0),MATCH(B$1,'Campus Enrol Disaggregation'!$P$4:$AC$4,0)) -> 31250 | C9: =INDEX('Campus Enrol Disaggregation'!$P$5:$AC$75,MATCH(Export_ControlTot!$A9,'Campus Enrol Disaggregation'!$O$5:$O$75,0),MATCH(C$1,'Campus Enrol Disaggregation'!$P$4:$AC$4,0)) -> 0 | D9: =INDEX('Campus Enrol Disaggregation'!$P$5:$AC$75,MATCH(Export_ControlTot!$A9,'Campus Enrol Disaggregation'!$O$5:$O$75,0),MATCH(D$1,'Campus Enrol Disaggregation'!$P$4:$AC$4,0)) -> 16650 | E9: =INDEX('Campus Enrol Disaggregation'!$P$5:$AC$75,MATCH(Export_ControlTot!$A9,'Campus Enrol Disaggregation'!$O$5:$O$75,0),MATCH(E$1,'Campus Enrol Disaggregation'!$P$4:$AC$4,0)) -> 3250 | F9: =INDEX('Campus Enrol Disaggregation'!$P$5:$AC$75,MATCH(Export_ControlTot!$A9,'Campus Enrol Disaggregation'!$O$5:$O$75,0),MATCH(F$1,'Campus Enrol Disaggregation'!$P$4:$AC$4,0)) -> 400 | G9: =INDEX('Campus Enrol Disaggregation'!$P$5:$AC$75,MATCH(Export_ControlTot!$A9,'Campus Enrol Disaggregation'!$O$5:$O$75,0),MATCH(G$1,'Campus Enrol Disaggregation'!$P$4:$AC$4,0)) -> 2450 | H9: =INDEX('Campus Enrol Disaggregation'!$P$5:$AC$75,MATCH(Export_ControlTot!$A9,'Campus Enrol Disaggregation'!$O$5:$O$75,0),MATCH(H$1,'Campus Enrol Disaggregation'!$P$4:$AC$4,0)) -> 25050 | I9: =INDEX('Campus Enrol Disaggregation'!$P$5:$AC$75,MATCH(Export_ControlTot!$A9,'Campus Enrol Disaggregation'!$O$5:$O$75,0),MATCH(I$1,'Campus Enrol Disaggregation'!$P$4:$AC$4,0)) -> 16000 | ... O9: =INDEX('Campus Enrol Disaggregation'!$P$5:$AC$75,MATCH(Export_ControlTot!$A9,'Campus Enrol Disaggregation'!$O$5:$O$75,0),MATCH(O$1,'Campus Enrol Disaggregation'!$P$4:$AC$4,0)) -> 0
A10: 1998 | B10: =INDEX('Campus Enrol Disaggregation'!$P$5:$AC$75,MATCH(Export_ControlTot!$A10,'Campus Enrol Disaggregation'!$O$5:$O$75,0),MATCH(B$1,'Campus Enrol Disaggregation'!$P$4:$AC$4,0)) -> 32200 | C10: =INDEX('Campus Enrol Disaggregation'!$P$5:$AC$75,MATCH(Export_ControlTot!$A10,'Campus Enrol Disaggregation'!$O$5:$O$75,0),MATCH(C$1,'Campus Enrol Disaggregation'!$P$4:$AC$4,0)) -> 0 | D10: =INDEX('Campus Enrol Disaggregation'!$P$5:$AC$75,MATCH(Export_ControlTot!$A10,'Campus Enrol Disaggregation'!$O$5:$O$75,0),MATCH(D$1,'Campus Enrol Disaggregation'!$P$4:$AC$4,0)) -> 13500 | E10: =INDEX('Campus Enrol Disaggregation'!$P$5:$AC$75,MATCH(Export_ControlTot!$A10,'Campus Enrol Disaggregation'!$O$5:$O$75,0),MATCH(E$1,'Campus Enrol Disaggregation'!$P$4:$AC$4,0)) -> 2650 | F10: =INDEX('Campus Enrol Disaggregation'!$P$5:$AC$75,MATCH(Export_ControlTot!$A10,'Campus Enrol Disaggregation'!$O$5:$O$75,0),MATCH(F$1,'Campus Enrol Disaggregation'!$P$4:$AC$4,0)) -> 300 | G10: =INDEX('Campus Enrol Disaggregation'!$P$5:$AC$75,MATCH(Export_ControlTot!$A10,'Campus Enrol Disaggregation'!$O$5:$O$75,0),MATCH(G$1,'Campus Enrol Disaggregation'!$P$4:$AC$4,0)) -> 2000 | H10: =INDEX('Campus Enrol Disaggregation'!$P$5:$AC$75,MATCH(Export_ControlTot!$A10,'Campus Enrol Disaggregation'!$O$5:$O$75,0),MATCH(H$1,'Campus Enrol Disaggregation'!$P$4:$AC$4,0)) -> 24200 | I10: =INDEX('Campus Enrol Disaggregation'!$P$5:$AC$75,MATCH(Export_ControlTot!$A10,'Campus Enrol Disaggregation'!$O$5:$O$75,0),MATCH(I$1,'Campus Enrol Disaggregation'!$P$4:$AC$4,0)) -> 18150 | ... O10: =INDEX('Campus Enrol Disaggregation'!$P$5:$AC$75,MATCH(Export_ControlTot!$A10,'Campus Enrol Disaggregation'!$O$5:$O$75,0),MATCH(O$1,'Campus Enrol Disaggregation'!$P$4:$AC$4,0)) -> 0
A11: 1999 | B11: =INDEX('Campus Enrol Disaggregation'!$P$5:$AC$75,MATCH(Export_ControlTot!$A11,'Campus Enrol Disaggregation'!$O$5:$O$75,0),MATCH(B$1,'Campus Enrol Disaggregation'!$P$4:$AC$4,0)) -> 32750 | C11: =INDEX('Campus Enrol Disaggregation'!$P$5:$AC$75,MATCH(Export_ControlTot!$A11,'Campus Enrol Disaggregation'!$O$5:$O$75,0),MATCH(C$1,'Campus Enrol Disaggregation'!$P$4:$AC$4,0)) -> 0 | D11: =INDEX('Campus Enrol Disaggregation'!$P$5:$AC$75,MATCH(Export_ControlTot!$A11,'Campus Enrol Disaggregation'!$O$5:$O$75,0),MATCH(D$1,'Campus Enrol Disaggregation'!$P$4:$AC$4,0)) -> 14550 | E11: =INDEX('Campus Enrol Disaggregation'!$P$5:$AC$75,MATCH(Export_ControlTot!$A11,'Campus Enrol Disaggregation'!$O$5:$O$75,0),MATCH(E$1,'Campus Enrol Disaggregation'!$P$4:$AC$4,0)) -> 2850 | F11: =INDEX('Campus Enrol Disaggregation'!$P$5:$AC$75,MATCH(Export_ControlTot!$A11,'Campus Enrol Disaggregation'!$O$5:$O$75,0),MATCH(F$1,'Campus Enrol Disaggregation'!$P$4:$AC$4,0)) -> 350 | G11: =INDEX('Campus Enrol Disaggregation'!$P$5:$AC$75,MATCH(Export_ControlTot!$A11,'Campus Enrol Disaggregation'!$O$5:$O$75,0),MATCH(G$1,'Campus Enrol Disaggregation'!$P$4:$AC$4,0)) -> 2150 | H11: =INDEX('Campus Enrol Disaggregation'!$P$5:$AC$75,MATCH(Export_ControlTot!$A11,'Campus Enrol Disaggregation'!$O$5:$O$75,0),MATCH(H$1,'Campus Enrol Disaggregation'!$P$4:$AC$4,0)) -> 24950 | I11: =INDEX('Campus Enrol Disaggregation'!$P$5:$AC$75,MATCH(Export_ControlTot!$A11,'Campus Enrol Disaggregation'!$O$5:$O$75,0),MATCH(I$1,'Campus Enrol Disaggregation'!$P$4:$AC$4,0)) -> 20050 | ... O11: =INDEX('Campus Enrol Disaggregation'!$P$5:$AC$75,MATCH(Export_ControlTot!$A11,'Campus Enrol Disaggregation'!$O$5:$O$75,0),MATCH(O$1,'Campus Enrol Disaggregation'!$P$4:$AC$4,0)) -> 0
A12: 2000 | B12: =INDEX('Campus Enrol Disaggregation'!$P$5:$AC$75,MATCH(Export_ControlTot!$A12,'Campus Enrol Disaggregation'!$O$5:$O$75,0),MATCH(B$1,'Campus Enrol Disaggregation'!$P$4:$AC$4,0)) -> 32550 | C12: =INDEX('Campus Enrol Disaggregation'!$P$5:$AC$75,MATCH(Export_ControlTot!$A12,'Campus Enrol Disaggregation'!$O$5:$O$75,0),MATCH(C$1,'Campus Enrol Disaggregation'!$P$4:$AC$4,0)) -> 800 | D12: =INDEX('Campus Enrol Disaggregation'!$P$5:$AC$75,MATCH(Export_ControlTot!$A12,'Campus Enrol Disaggregation'!$O$5:$O$75,0),MATCH(D$1,'Campus Enrol Disaggregation'!$P$4:$AC$4,0)) -> 14750 | E12: =INDEX('Campus Enrol Disaggregation'!$P$5:$AC$75,MATCH(Export_ControlTot!$A12,'Campus Enrol Disaggregation'!$O$5:$O$75,0),MATCH(E$1,'Campus Enrol Disaggregation'!$P$4:$AC$4,0)) -> 2900 | F12: =INDEX('Campus Enrol Disaggregation'!$P$5:$AC$75,MATCH(Export_ControlTot!$A12,'Campus Enrol Disaggregation'!$O$5:$O$75,0),MATCH(F$1,'Campus Enrol Disaggregation'!$P$4:$AC$4,0)) -> 350 | G12: =INDEX('Campus Enrol Disaggregation'!$P$5:$AC$75,MATCH(Export_ControlTot!$A12,'Campus Enrol Disaggregation'!$O$5:$O$75,0),MATCH(G$1,'Campus Enrol Disaggregation'!$P$4:$AC$4,0)) -> 2200 | H12: =INDEX('Campus Enrol Disaggregation'!$P$5:$AC$75,MATCH(Export_ControlTot!$A12,'Campus Enrol Disaggregation'!$O$5:$O$75,0),MATCH(H$1,'Campus Enrol Disaggregation'!$P$4:$AC$4,0)) -> 24150 | I12: =INDEX('Campus Enrol Disaggregation'!$P$5:$AC$75,MATCH(Export_ControlTot!$A12,'Campus Enrol Disaggregation'!$O$5:$O$75,0),MATCH(I$1,'Campus Enrol Disaggregation'!$P$4:$AC$4,0)) -> 20950 | ... O12: =INDEX('Campus Enrol Disaggregation'!$P$5:$AC$75,MATCH(Export_ControlTot!$A12,'Campus Enrol Disaggregation'!$O$5:$O$75,0),MATCH(O$1,'Campus Enrol Disaggregation'!$P$4:$AC$4,0)) -> 2400
A13: 2001 | B13: =INDEX('Campus Enrol Disaggregation'!$P$5:$AC$75,MATCH(Export_ControlTot!$A13,'Campus Enrol Disaggregation'!$O$5:$O$75,0),MATCH(B$1,'Campus Enrol Disaggregation'!$P$4:$AC$4,0)) -> 32750 | C13: =INDEX('Campus Enrol Disaggregation'!$P$5:$AC$75,MATCH(Export_ControlTot!$A13,'Campus Enrol Disaggregation'!$O$5:$O$75,0),MATCH(C$1,'Campus Enrol Disaggregation'!$P$4:$AC$4,0)) -> 1050 | D13: =INDEX('Campus Enrol Disaggregation'!$P$5:$AC$75,MATCH(Export_ControlTot!$A13,'Campus Enrol Disaggregation'!$O$5:$O$75,0),MATCH(D$1,'Campus Enrol Disaggregation'!$P$4:$AC$4,0)) -> 16200 | E13: =INDEX('Campus Enrol Disaggregation'!$P$5:$AC$75,MATCH(Export_ControlTot!$A13,'Campus Enrol Disaggregation'!$O$5:$O$75,0),MATCH(E$1,'Campus Enrol Disaggregation'!$P$4:$AC$4,0)) -> 3150 | F13: =INDEX('Campus Enrol Disaggregation'!$P$5:$AC$75,MATCH(Export_ControlTot!$A13,'Campus Enrol Disaggregation'!$O$5:$O$75,0),MATCH(F$1,'Campus Enrol Disaggregation'!$P$4:$AC$4,0)) -> 400 | G13: =INDEX('Campus Enrol Disaggregation'!$P$5:$AC$75,MATCH(Export_ControlTot!$A13,'Campus Enrol Disaggregation'!$O$5:$O$75,0),MATCH(G$1,'Campus Enrol Disaggregation'!$P$4:$AC$4,0)) -> 2400 | H13: =INDEX('Campus Enrol Disaggregation'!$P$5:$AC$75,MATCH(Export_ControlTot!$A13,'Campus Enrol Disaggregation'!$O$5:$O$75,0),MATCH(H$1,'Campus Enrol Disaggregation'!$P$4:$AC$4,0)) -> 26800 | I13: =INDEX('Campus Enrol Disaggregation'!$P$5:$AC$75,MATCH(Export_ControlTot!$A13,'Campus Enrol Disaggregation'!$O$5:$O$75,0),MATCH(I$1,'Campus Enrol Disaggregation'!$P$4:$AC$4,0)) -> 22600 | ... O13: =INDEX('Campus Enrol Disaggregation'!$P$5:$AC$75,MATCH(Export_ControlTot!$A13,'Campus Enrol Disaggregation'!$O$5:$O$75,0),MATCH(O$1,'Campus Enrol Disaggregation'!$P$4:$AC$4,0)) -> 2450
A14: 2002 | B14: =INDEX('Campus Enrol Disaggregation'!$P$5:$AC$75,MATCH(Export_ControlTot!$A14,'Campus Enrol Disaggregation'!$O$5:$O$75,0),MATCH(B$1,'Campus Enrol Disaggregation'!$P$4:$AC$4,0)) -> 32400 | C14: =INDEX('Campus Enrol Disaggregation'!$P$5:$AC$75,MATCH(Export_ControlTot!$A14,'Campus Enrol Disaggregation'!$O$5:$O$75,0),MATCH(C$1,'Campus Enrol Disaggregation'!$P$4:$AC$4,0)) -> 1100 | D14: =INDEX('Campus Enrol Disaggregation'!$P$5:$AC$75,MATCH(Export_ControlTot!$A14,'Campus Enrol Disaggregation'!$O$5:$O$75,0),MATCH(D$1,'Campus Enrol Disaggregation'!$P$4:$AC$4,0)) -> 15950 | E14: =INDEX('Campus Enrol Disaggregation'!$P$5:$AC$75,MATCH(Export_ControlTot!$A14,'Campus Enrol Disaggregation'!$O$5:$O$75,0),MATCH(E$1,'Campus Enrol Disaggregation'!$P$4:$AC$4,0)) -> 3100 | F14: =INDEX('Campus Enrol Disaggregation'!$P$5:$AC$75,MATCH(Export_ControlTot!$A14,'Campus Enrol Disaggregation'!$O$5:$O$75,0),MATCH(F$1,'Campus Enrol Disaggregation'!$P$4:$AC$4,0)) -> 400 | G14: =INDEX('Campus Enrol Disaggregation'!$P$5:$AC$75,MATCH(Export_ControlTot!$A14,'Campus Enrol Disaggregation'!$O$5:$O$75,0),MATCH(G$1,'Campus Enrol Disaggregation'!$P$4:$AC$4,0)) -> 2400 | H14: =INDEX('Campus Enrol Disaggregation'!$P$5:$AC$75,MATCH(Export_ControlTot!$A14,'Campus Enrol Disaggregation'!$O$5:$O$75,0),MATCH(H$1,'Campus Enrol Disaggregation'!$P$4:$AC$4,0)) -> 27450 | I14: =INDEX('Campus Enrol Disaggregation'!$P$5:$AC$75,MATCH(Export_ControlTot!$A14,'Campus Enrol Disaggregation'!$O$5:$O$75,0),MATCH(I$1,'Campus Enrol Disaggregation'!$P$4:$AC$4,0)) -> 23600 | ... O14: =INDEX('Campus Enrol Disaggregation'!$P$5:$AC$75,MATCH(Export_ControlTot!$A14,'Campus Enrol Disaggregation'!$O$5:$O$75,0),MATCH(O$1,'Campus Enrol Disaggregation'!$P$4:$AC$4,0)) -> 2350
A15: 2003 | B15: =INDEX('Campus Enrol Disaggregation'!$P$5:$AC$75,MATCH(Export_ControlTot!$A15,'Campus Enrol Disaggregation'!$O$5:$O$75,0),MATCH(B$1,'Campus Enrol Disaggregation'!$P$4:$AC$4,0)) -> 33000 | C15: =INDEX('Campus Enrol Disaggregation'!$P$5:$AC$75,MATCH(Export_ControlTot!$A15,'Campus Enrol Disaggregation'!$O$5:$O$75,0),MATCH(C$1,'Campus Enrol Disaggregation'!$P$4:$AC$4,0)) -> 1250 | D15: =INDEX('Campus Enrol Disaggregation'!$P$5:$AC$75,MATCH(Export_ControlTot!$A15,'Campus Enrol Disaggregation'!$O$5:$O$75,0),MATCH(D$1,'Campus Enrol Disaggregation'!$P$4:$AC$4,0)) -> 16450 | E15: =INDEX('Campus Enrol Disaggregation'!$P$5:$AC$75,MATCH(Export_ControlTot!$A15,'Campus Enrol Disaggregation'!$O$5:$O$75,0),MATCH(E$1,'Campus Enrol Disaggregation'!$P$4:$AC$4,0)) -> 3200 | F15: =INDEX('Campus Enrol Disaggregation'!$P$5:$AC$75,MATCH(Export_ControlTot!$A15,'Campus Enrol Disaggregation'!$O$5:$O$75,0),MATCH(F$1,'Campus Enrol Disaggregation'!$P$4:$AC$4,0)) -> 400 | G15: =INDEX('Campus Enrol Disaggregation'!$P$5:$AC$75,MATCH(Export_ControlTot!$A15,'Campus Enrol Disaggregation'!$O$5:$O$75,0),MATCH(G$1,'Campus Enrol Disaggregation'!$P$4:$AC$4,0)) -> 2450 | H15: =INDEX('Campus Enrol Disaggregation'!$P$5:$AC$75,MATCH(Export_ControlTot!$A15,'Campus Enrol Disaggregation'!$O$5:$O$75,0),MATCH(H$1,'Campus Enrol Disaggregation'!$P$4:$AC$4,0)) -> 27550 | I15: =INDEX('Campus Enrol Disaggregation'!$P$5:$AC$75,MATCH(Export_ControlTot!$A15,'Campus Enrol Disaggregation'!$O$5:$O$75,0),MATCH(I$1,'Campus Enrol Disaggregation'!$P$4:$AC$4,0)) -> 23800 | ... O15: =INDEX('Campus Enrol Disaggregation'!$P$5:$AC$75,MATCH(Export_ControlTot!$A15,'Campus Enrol Disaggregation'!$O$5:$O$75,0),MATCH(O$1,'Campus Enrol Disaggregation'!$P$4:$AC$4,0)) -> 2450
A16: 2004 | B16: =INDEX('Campus Enrol Disaggregation'!$P$5:$AC$75,MATCH(Export_ControlTot!$A16,'Campus Enrol Disaggregation'!$O$5:$O$75,0),MATCH(B$1,'Campus Enrol Disaggregation'!$P$4:$AC$4,0)) -> 34350 | C16: =INDEX('Campus Enrol Disaggregation'!$P$5:$AC$75,MATCH(Export_ControlTot!$A16,'Campus Enrol Disaggregation'!$O$5:$O$75,0),MATCH(C$1,'Campus Enrol Disaggregation'!$P$4:$AC$4,0)) -> 1250 | D16: =INDEX('Campus Enrol Disaggregation'!$P$5:$AC$75,MATCH(Export_ControlTot!$A16,'Campus Enrol Disaggregation'!$O$5:$O$75,0),MATCH(D$1,'Campus Enrol Disaggregation'!$P$4:$AC$4,0)) -> 16900 | E16: =INDEX('Campus Enrol Disaggregation'!$P$5:$AC$75,MATCH(Export_ControlTot!$A16,'Campus Enrol Disaggregation'!$O$5:$O$75,0),MATCH(E$1,'Campus Enrol Disaggregation'!$P$4:$AC$4,0)) -> 3300 | F16: =INDEX('Campus Enrol Disaggregation'!$P$5:$AC$75,MATCH(Export_ControlTot!$A16,'Campus Enrol Disaggregation'!$O$5:$O$75,0),MATCH(F$1,'Campus Enrol Disaggregation'!$P$4:$AC$4,0)) -> 400 | G16: =INDEX('Campus Enrol Disaggregation'!$P$5:$AC$75,MATCH(Export_ControlTot!$A16,'Campus Enrol Disaggregation'!$O$5:$O$75,0),MATCH(G$1,'Campus Enrol Disaggregation'!$P$4:$AC$4,0)) -> 2500 | H16: =INDEX('Campus Enrol Disaggregation'!$P$5:$AC$75,MATCH(Export_ControlTot!$A16,'Campus Enrol Disaggregation'!$O$5:$O$75,0),MATCH(H$1,'Campus Enrol Disaggregation'!$P$4:$AC$4,0)) -> 28000 | I16: =INDEX('Campus Enrol Disaggregation'!$P$5:$AC$75,MATCH(Export_ControlTot!$A16,'Campus Enrol Disaggregation'!$O$5:$O$75,0),MATCH(I$1,'Campus Enrol Disaggregation'!$P$4:$AC$4,0)) -> 24150 | ... O16: =INDEX('Campus Enrol Disaggregation'!$P$5:$AC$75,MATCH(Export_ControlTot!$A16,'Campus Enrol Disaggregation'!$O$5:$O$75,0),MATCH(O$1,'Campus Enrol Disaggregation'!$P$4:$AC$4,0)) -> 2400
A17: 2005 | B17: =INDEX('Campus Enrol Disaggregation'!$P$5:$AC$75,MATCH(Export_ControlTot!$A17,'Campus Enrol Disaggregation'!$O$5:$O$75,0),MATCH(B$1,'Campus Enrol Disaggregation'!$P$4:$AC$4,0)) -> 34050 | C17: =INDEX('Campus Enrol Disaggregation'!$P$5:$AC$75,MATCH(Export_ControlTot!$A17,'Campus Enrol Disaggregation'!$O$5:$O$75,0),MATCH(C$1,'Campus Enrol Disaggregation'!$P$4:$AC$4,0)) -> 1250 | D17: =INDEX('Campus Enrol Disaggregation'!$P$5:$AC$75,MATCH(Export_ControlTot!$A17,'Campus Enrol Disaggregation'!$O$5:$O$75,0),MATCH(D$1,'Campus Enrol Disaggregation'!$P$4:$AC$4,0)) -> 16500 | E17: =INDEX('Campus Enrol Disaggregation'!$P$5:$AC$75,MATCH(Export_ControlTot!$A17,'Campus Enrol Disaggregation'!$O$5:$O$75,0),MATCH(E$1,'Campus Enrol Disaggregation'!$P$4:$AC$4,0)) -> 3200 | F17: =INDEX('Campus Enrol Disaggregation'!$P$5:$AC$75,MATCH(Export_ControlTot!$A17,'Campus Enrol Disaggregation'!$O$5:$O$75,0),MATCH(F$1,'Campus Enrol Disaggregation'!$P$4:$AC$4,0)) -> 400 | G17: =INDEX('Campus Enrol Disaggregation'!$P$5:$AC$75,MATCH(Export_ControlTot!$A17,'Campus Enrol Disaggregation'!$O$5:$O$75,0),MATCH(G$1,'Campus Enrol Disaggregation'!$P$4:$AC$4,0)) -> 2450 | H17: =INDEX('Campus Enrol Disaggregation'!$P$5:$AC$75,MATCH(Export_ControlTot!$A17,'Campus Enrol Disaggregation'!$O$5:$O$75,0),MATCH(H$1,'Campus Enrol Disaggregation'!$P$4:$AC$4,0)) -> 29600 | I17: =INDEX('Campus Enrol Disaggregation'!$P$5:$AC$75,MATCH(Export_ControlTot!$A17,'Campus Enrol Disaggregation'!$O$5:$O$75,0),MATCH(I$1,'Campus Enrol Disaggregation'!$P$4:$AC$4,0)) -> 24500 | ... O17: =INDEX('Campus Enrol Disaggregation'!$P$5:$AC$75,MATCH(Export_ControlTot!$A17,'Campus Enrol Disaggregation'!$O$5:$O$75,0),MATCH(O$1,'Campus Enrol Disaggregation'!$P$4:$AC$4,0)) -> 2450
A18: 2006 | B18: =INDEX('Campus Enrol Disaggregation'!$P$5:$AC$75,MATCH(Export_ControlTot!$A18,'Campus Enrol Disaggregation'!$O$5:$O$75,0),MATCH(B$1,'Campus Enrol Disaggregation'!$P$4:$AC$4,0)) -> 34200 | C18: =INDEX('Campus Enrol Disaggregation'!$P$5:$AC$75,MATCH(Export_ControlTot!$A18,'Campus Enrol Disaggregation'!$O$5:$O$75,0),MATCH(C$1,'Campus Enrol Disaggregation'!$P$4:$AC$4,0)) -> 1300 | D18: =INDEX('Campus Enrol Disaggregation'!$P$5:$AC$75,MATCH(Export_ControlTot!$A18,'Campus Enrol Disaggregation'!$O$5:$O$75,0),MATCH(D$1,'Campus Enrol Disaggregation'!$P$4:$AC$4,0)) -> 16600 | E18: =INDEX('Campus Enrol Disaggregation'!$P$5:$AC$75,MATCH(Export_ControlTot!$A18,'Campus Enrol Disaggregation'!$O$5:$O$75,0),MATCH(E$1,'Campus Enrol Disaggregation'!$P$4:$AC$4,0)) -> 3250 | F18: =INDEX('Campus Enrol Disaggregation'!$P$5:$AC$75,MATCH(Export_ControlTot!$A18,'Campus Enrol Disaggregation'!$O$5:$O$75,0),MATCH(F$1,'Campus Enrol Disaggregation'!$P$4:$AC$4,0)) -> 400 | G18: =INDEX('Campus Enrol Disaggregation'!$P$5:$AC$75,MATCH(Export_ControlTot!$A18,'Campus Enrol Disaggregation'!$O$5:$O$75,0),MATCH(G$1,'Campus Enrol Disaggregation'!$P$4:$AC$4,0)) -> 2450 | H18: =INDEX('Campus Enrol Disaggregation'!$P$5:$AC$75,MATCH(Export_ControlTot!$A18,'Campus Enrol Disaggregation'!$O$5:$O$75,0),MATCH(H$1,'Campus Enrol Disaggregation'!$P$4:$AC$4,0)) -> 29550 | I18: =INDEX('Campus Enrol Disaggregation'!$P$5:$AC$75,MATCH(Export_ControlTot!$A18,'Campus Enrol Disaggregation'!$O$5:$O$75,0),MATCH(I$1,'Campus Enrol Disaggregation'!$P$4:$AC$4,0)) -> 23300 | ... O18: =INDEX('Campus Enrol Disaggregation'!$P$5:$AC$75,MATCH(Export_ControlTot!$A18,'Campus Enrol Disaggregation'!$O$5:$O$75,0),MATCH(O$1,'Campus Enrol Disaggregation'!$P$4:$AC$4,0)) -> 2500
A19: 2007 | B19: =INDEX('Campus Enrol Disaggregation'!$P$5:$AC$75,MATCH(Export_ControlTot!$A19,'Campus Enrol Disaggregation'!$O$5:$O$75,0),MATCH(B$1,'Campus Enrol Disaggregation'!$P$4:$AC$4,0)) -> 34150 | C19: =INDEX('Campus Enrol Disaggregation'!$P$5:$AC$75,MATCH(Export_ControlTot!$A19,'Campus Enrol Disaggregation'!$O$5:$O$75,0),MATCH(C$1,'Campus Enrol Disaggregation'!$P$4:$AC$4,0)) -> 1300 | D19: =INDEX('Campus Enrol Disaggregation'!$P$5:$AC$75,MATCH(Export_ControlTot!$A19,'Campus Enrol Disaggregation'!$O$5:$O$75,0),MATCH(D$1,'Campus Enrol Disaggregation'!$P$4:$AC$4,0)) -> 17250 | E19: =INDEX('Campus Enrol Disaggregation'!$P$5:$AC$75,MATCH(Export_ControlTot!$A19,'Campus Enrol Disaggregation'!$O$5:$O$75,0),MATCH(E$1,'Campus Enrol Disaggregation'!$P$4:$AC$4,0)) -> 3350 | F19: =INDEX('Campus Enrol Disaggregation'!$P$5:$AC$75,MATCH(Export_ControlTot!$A19,'Campus Enrol Disaggregation'!$O$5:$O$75,0),MATCH(F$1,'Campus Enrol Disaggregation'!$P$4:$AC$4,0)) -> 400 | G19: =INDEX('Campus Enrol Disaggregation'!$P$5:$AC$75,MATCH(Export_ControlTot!$A19,'Campus Enrol Disaggregation'!$O$5:$O$75,0),MATCH(G$1,'Campus Enrol Disaggregation'!$P$4:$AC$4,0)) -> 2550 | H19: =INDEX('Campus Enrol Disaggregation'!$P$5:$AC$75,MATCH(Export_ControlTot!$A19,'Campus Enrol Disaggregation'!$O$5:$O$75,0),MATCH(H$1,'Campus Enrol Disaggregation'!$P$4:$AC$4,0)) -> 27150 | I19: =INDEX('Campus Enrol Disaggregation'!$P$5:$AC$75,MATCH(Export_ControlTot!$A19,'Campus Enrol Disaggregation'!$O$5:$O$75,0),MATCH(I$1,'Campus Enrol Disaggregation'!$P$4:$AC$4,0)) -> 23850 | ... O19: =INDEX('Campus Enrol Disaggregation'!$P$5:$AC$75,MATCH(Export_ControlTot!$A19,'Campus Enrol Disaggregation'!$O$5:$O$75,0),MATCH(O$1,'Campus Enrol Disaggregation'!$P$4:$AC$4,0)) -> 2650
A20: 2008 | B20: =INDEX('Campus Enrol Disaggregation'!$P$5:$AC$75,MATCH(Export_ControlTot!$A20,'Campus Enrol Disaggregation'!$O$5:$O$75,0),MATCH(B$1,'Campus Enrol Disaggregation'!$P$4:$AC$4,0)) -> 34250 | C20: =INDEX('Campus Enrol Disaggregation'!$P$5:$AC$75,MATCH(Export_ControlTot!$A20,'Campus Enrol Disaggregation'!$O$5:$O$75,0),MATCH(C$1,'Campus Enrol Disaggregation'!$P$4:$AC$4,0)) -> 1400 | D20: =INDEX('Campus Enrol Disaggregation'!$P$5:$AC$75,MATCH(Export_ControlTot!$A20,'Campus Enrol Disaggregation'!$O$5:$O$75,0),MATCH(D$1,'Campus Enrol Disaggregation'!$P$4:$AC$4,0)) -> 20100 | E20: =INDEX('Campus Enrol Disaggregation'!$P$5:$AC$75,MATCH(Export_ControlTot!$A20,'Campus Enrol Disaggregation'!$O$5:$O$75,0),MATCH(E$1,'Campus Enrol Disaggregation'!$P$4:$AC$4,0)) -> 3900 | F20: =INDEX('Campus Enrol Disaggregation'!$P$5:$AC$75,MATCH(Export_ControlTot!$A20,'Campus Enrol Disaggregation'!$O$5:$O$75,0),MATCH(F$1,'Campus Enrol Disaggregation'!$P$4:$AC$4,0)) -> 500 | G20: =INDEX('Campus Enrol Disaggregation'!$P$5:$AC$75,MATCH(Export_ControlTot!$A20,'Campus Enrol Disaggregation'!$O$5:$O$75,0),MATCH(G$1,'Campus Enrol Disaggregation'!$P$4:$AC$4,0)) -> 3000 | H20: =INDEX('Campus Enrol Disaggregation'!$P$5:$AC$75,MATCH(Export_ControlTot!$A20,'Campus Enrol Disaggregation'!$O$5:$O$75,0),MATCH(H$1,'Campus Enrol Disaggregation'!$P$4:$AC$4,0)) -> 27300 | I20: =INDEX('Campus Enrol Disaggregation'!$P$5:$AC$75,MATCH(Export_ControlTot!$A20,'Campus Enrol Disaggregation'!$O$5:$O$75,0),MATCH(I$1,'Campus Enrol Disaggregation'!$P$4:$AC$4,0)) -> 27050 | ... O20: =INDEX('Campus Enrol Disaggregation'!$P$5:$AC$75,MATCH(Export_ControlTot!$A20,'Campus Enrol Disaggregation'!$O$5:$O$75,0),MATCH(O$1,'Campus Enrol Disaggregation'!$P$4:$AC$4,0)) -> 2850
... A72: 2060 | B72: =INDEX('Campus Enrol Disaggregation'!$P$5:$AC$75,MATCH(Export_ControlTot!$A72,'Campus Enrol Disaggregation'!$O$5:$O$75,0),MATCH(B$1,'Campus Enrol Disaggregation'!$P$4:$AC$4,0)) -> 39300 | C72: =INDEX('Campus Enrol Disaggregation'!$P$5:$AC$75,MATCH(Export_ControlTot!$A72,'Campus Enrol Disaggregation'!$O$5:$O$75,0),MATCH(C$1,'Campus Enrol Disaggregation'!$P$4:$AC$4,0)) -> 3200 | D72: =INDEX('Campus Enrol Disaggregation'!$P$5:$AC$75,MATCH(Export_ControlTot!$A72,'Campus Enrol Disaggregation'!$O$5:$O$75,0),MATCH(D$1,'Campus Enrol Disaggregation'!$P$4:$AC$4,0)) -> 29400 | E72: =INDEX('Campus Enrol Disaggregation'!$P$5:$AC$75,MATCH(Export_ControlTot!$A72,'Campus Enrol Disaggregation'!$O$5:$O$75,0),MATCH(E$1,'Campus Enrol Disaggregation'!$P$4:$AC$4,0)) -> 5750 | F72: =INDEX('Campus Enrol Disaggregation'!$P$5:$AC$75,MATCH(Export_ControlTot!$A72,'Campus Enrol Disaggregation'!$O$5:$O$75,0),MATCH(F$1,'Campus Enrol Disaggregation'!$P$4:$AC$4,0)) -> 700 | G72: =INDEX('Campus Enrol Disaggregation'!$P$5:$AC$75,MATCH(Export_ControlTot!$A72,'Campus Enrol Disaggregation'!$O$5:$O$75,0),MATCH(G$1,'Campus Enrol Disaggregation'!$P$4:$AC$4,0)) -> 4400 | H72: =INDEX('Campus Enrol Disaggregation'!$P$5:$AC$75,MATCH(Export_ControlTot!$A72,'Campus Enrol Disaggregation'!$O$5:$O$75,0),MATCH(H$1,'Campus Enrol Disaggregation'!$P$4:$AC$4,0)) -> 45500 | I72: =INDEX('Campus Enrol Disaggregation'!$P$5:$AC$75,MATCH(Export_ControlTot!$A72,'Campus Enrol Disaggregation'!$O$5:$O$75,0),MATCH(I$1,'Campus Enrol Disaggregation'!$P$4:$AC$4,0)) -> 68000 | ... O72: =INDEX('Campus Enrol Disaggregation'!$P$5:$AC$75,MATCH(Export_ControlTot!$A72,'Campus Enrol Disaggregation'!$O$5:$O$75,0),MATCH(O$1,'Campus Enrol Disaggregation'!$P$4:$AC$4,0)) -> 3500

Sheet Export_Factors
A1: ;INDEX | B1: ENSIGN | C1: WESTMIN | D1: UOFU_Main | E1: UofU_Med | F1: WSU_Main | G1: WSU_Davis | H1: WSU_West | I1: SLCC_MAIN | J1: SLCC_SC | K1: SLCC_JD | L1: SLCC_Mead | M1: SLCC_ML | N1: SLCC_LB | O1: SLCC_HL | P1: SLCC_Airp | Q1: SLCC_West | R1: SLCC_HM | S1: BYU | T1: UVU_Main | U1: UVU_Geneva | V1: UVU_Lehi | W1: UVU_Vineyard | X1: UVU_Payson | Y1: Var_Name
A2: 1 | B2: =VLOOKUP(B1,'calc%concurrent'!$A$2:$B$15,2,FALSE) -> 0.1005 | C2: =VLOOKUP(C1,'calc%concurrent'!$A$2:$B$15,2,FALSE) -> 0.0115625 | D2: =VLOOKUP(D1,'calc%concurrent'!$A$2:$B$15,2,FALSE) -> 0.026040514 | E2: =D2 -> 0.026040514 | F2: =VLOOKUP(F1,'calc%concurrent'!$A$2:$B$15,2,FALSE) -> 0.21501654 | G2: =VLOOKUP(G1,'calc%concurrent'!$A$2:$B$15,2,FALSE) -> 0.30851477 | H2: =G2 -> 0.30851477 | I2: =VLOOKUP(I1,'calc%concurrent'!$A$2:$B$15,2,FALSE) -> 0.34092451 | J2: =VLOOKUP(J1,'calc%concurrent'!$A$2:$B$15,2,FALSE) -> 0.34092451 | K2: =VLOOKUP(K1,'calc%concurrent'!$A$2:$B$15,2,FALSE) -> 0.34092451 | L2: =K2 -> 0.34092451 | M2: =VLOOKUP(M1,'calc%concurrent'!$A$2:$B$15,2,FALSE) -> 0.34092451 | N2: =M2 -> 0.34092451 | O2: =N2 -> 0.34092451 | P2: =O2 -> 0.34092451 | Q2: =P2 -> 0.34092451 | R2: =Q2 -> 0.34092451 | S2: =VLOOKUP(S$1,'calc%concurrent'!$A$2:$B$15,2,FALSE) -> 0.026040514 | T2: =VLOOKUP(T1,'calc%concurrent'!$A$2:$B$15,2,FALSE) -> 0.26992029 | U2: =T2 -> 0.26992029 | V2: =VLOOKUP(V1,'calc%concurrent'!$A$2:$B$15,2,FALSE) -> 0.26992029 | W2: =VLOOKUP(W1,'calc%concurrent'!$A$2:$B$15,2,FALSE) -> 0.26992029 | X2: =VLOOKUP(X1,'calc%concurrent'!$A$2:$B$15,2,FALSE) -> 0.26992029 | Y2: Pct_Remove
A3: 2 | B3: =VLOOKUP(B$1,'FTE Rate Calcs'!$A$2:$B$15,2,FALSE) -> 1.4528829 | C3: =VLOOKUP(C$1,'FTE Rate Calcs'!$A$2:$B$15,2,FALSE) -> 1.2591684 | D3: =VLOOKUP(D$1,'FTE Rate Calcs'!$A$2:$B$15,2,FALSE) -> 1.3199787 | E3: =D3 -> 1.3199787 | F3: =VLOOKUP(F$1,'FTE Rate Calcs'!$A$2:$B$15,2,FALSE) -> 1.9089034 | G3: =VLOOKUP(G$1,'FTE Rate Calcs'!$A$2:$B$15,2,FALSE) -> 1.9089034 | H3: =G3 -> 1.9089034 | I3: =VLOOKUP(I$1,'FTE Rate Calcs'!$A$2:$B$15,2,FALSE) -> 2.4944485 | J3: =VLOOKUP(J$1,'FTE Rate Calcs'!$A$2:$B$15,2,FALSE) -> 2.4944485 | K3: =VLOOKUP(K$1,'FTE Rate Calcs'!$A$2:$B$15,2,FALSE) -> 2.4944485 | L3: =K3 -> 2.4944485 | M3: =VLOOKUP(M$1,'FTE Rate Calcs'!$A$2:$B$15,2,FALSE) -> 2.4944485 | N3: =M3 -> 2.4944485 | O3: =N3 -> 2.4944485 | P3: =O3 -> 2.4944485 | Q3: =P3 -> 2.4944485 | R3: =Q3 -> 2.4944485 | S3: =VLOOKUP(S$1,'FTE Rate Calcs'!$A$2:$B$15,2,FALSE) -> 1.1631452 | T3: =VLOOKUP(T$1,'FTE Rate Calcs'!$A$2:$B$15,2,FALSE) -> 1.6817349 | U3: =T3 -> 1.6817349 | V3: =VLOOKUP(V$1,'FTE Rate Calcs'!$A$2:$B$15,2,FALSE) -> 1.6817349 | W3: =VLOOKUP(W$1,'FTE Rate Calcs'!$A$2:$B$15,2,FALSE) -> 1.6817349 | X3: =VLOOKUP(X$1,'FTE Rate Calcs'!$A$2:$B$15,2,FALSE) -> 1.6817349 | Y3: FTERate
A4: 3 | B4: =VLOOKUP(B$1,'HBC Rates'!$A$2:$B$15,2,FALSE) -> 0.9301 | C4: =VLOOKUP(C$1,'HBC Rates'!$A$2:$B$15,2,FALSE) -> 0.9301 | D4: =VLOOKUP(D$1,'HBC Rates'!$A$2:$B$15,2,FALSE) -> 0.9301 | E4: =D4 -> 0.9301 | F4: =VLOOKUP(F$1,'HBC Rates'!$A$2:$B$15,2,FALSE) -> 0.83 | G4: =VLOOKUP(G$1,'HBC Rates'!$A$2:$B$15,2,FALSE) -> 0.677 | H4: =G4 -> 0.677 | I4: =VLOOKUP(I$1,'HBC Rates'!$A$2:$B$15,2,FALSE) -> 0.6219 | J4: =VLOOKUP(J$1,'HBC Rates'!$A$2:$B$15,2,FALSE) -> 0.6422 | K4: =VLOOKUP(K$1,'HBC Rates'!$A$2:$B$15,2,FALSE) -> 0.5687 | L4: =K4 -> 0.5687 | M4: =VLOOKUP(M$1,'HBC Rates'!$A$2:$B$15,2,FALSE) -> 0.6158 | N4: =M4 -> 0.6158 | O4: =N4 -> 0.6158 | P4: =O4 -> 0.6158 | Q4: =P4 -> 0.6158 | R4: =Q4 -> 0.6158 | S4: =VLOOKUP(S$1,'HBC Rates'!$A$2:$B$15,2,FALSE) -> 0.9301 | T4: =VLOOKUP(T$1,'HBC Rates'!$A$2:$B$15,2,FALSE) -> 0.9452 | U4: =T4 -> 0.9452 | V4: =VLOOKUP(V$1,'HBC Rates'!$A$2:$B$15,2,FALSE) -> 0.9452 | W4: =VLOOKUP(W$1,'HBC Rates'!$A$2:$B$15,2,FALSE) -> 0.9452 | X4: =VLOOKUP(X$1,'HBC Rates'!$A$2:$B$15,2,FALSE) -> 0.9452 | Y4: HBCRates
A6: Note:
A7: Removal means concurrent, online degree etc.
A8: FTERate = FTE / Total Headcount, Total Headcount includes online and concurrent enrollment

Sheet Campus Enrol Disaggregation
O1: Enrollment Projections by Campus
O2: School: | P2: =IFERROR((FIND("_",P4)),P4) -> BYU | Q2: =IFERROR((FIND("_",Q4)),Q4) -> ENSIGN | R2: =IF(FIND("_",R4),LEFT(R4,FIND("_",R4)-1),R4) -> SLCC | S2: =IF(FIND("_",S4),LEFT(S4,FIND("_",S4)-1),S4) -> SLCC | T2: =IF(FIND("_",T4),LEFT(T4,FIND("_",T4)-1),T4) -> SLCC | U2: =IF(FIND("_",U4),LEFT(U4,FIND("_",U4)-1),U4) -> SLCC | V2: =IF(FIND("_",V4),LEFT(V4,FIND("_",V4)-1),V4) -> UOFU | AA2: =IF(FIND("_",AA4),LEFT(AA4,FIND("_",AA4)-1),AA4) -> WSU | AB2: =IF(FIND("_",AB4),LEFT(AB4,FIND("_",AB4)-1),AB4) -> WSU | AC2: =IFERROR((FIND("_",AC4)),AC4) -> WESTMIN
O3: % of School: | P3: 1 | Q3: 1 | R3: ='USHE 2020 Campus Totals'!D3 -> 0.68409987 | S3: ='USHE 2020 Campus Totals'!D6 -> 0.13337714 | T3: ='USHE 2020 Campus Totals'!D7 -> 0.016162943 | U3: ='USHE 2020 Campus Totals'!D10 -> 0.10175208 | V3: ='USHE 2020 Campus Totals'!D19 -> 0.96822825 | AA3: ='USHE 2020 Campus Totals'!D23 -> 0.81142857 | AB3: ='USHE 2020 Campus Totals'!D26 -> 0.162818 | AC3: 1
O4: Year | P4: BYU | Q4: ENSIGN | R4: SLCC_MAIN | S4: SLCC_JD | T4: SLCC_ML | U4: SLCC_SC | V4: UOFU_Main | W4: UVU_Main | X4: UVU_Lehi | Y4: UVU_Payson | Z4: UVU_Vineyard | AA4: WSU_Main | AB4: WSU_Davis | AC4: WESTMIN | AD4: Total
O5: 1990 | P5: =MROUND(P$3*INDEX('College Enrollment Projections'!$AJ$2:$AP$72,MATCH('Campus Enrol Disaggregation'!$O5,'College Enrollment Projections'!$AI$2:$AI$72,0),MATCH('Campus Enrol Disaggregation'!P$2,'College Enrollment Projections'!$AJ$1:$AP$1,0)),50) -> 30450 | Q5: =MROUND(Q$3*INDEX('College Enrollment Projections'!$AJ$2:$AP$72,MATCH('Campus Enrol Disaggregation'!$O5,'College Enrollment Projections'!$AI$2:$AI$72,0),MATCH('Campus Enrol Disaggregation'!Q$2,'College Enrollment Projections'!$AJ$1:$AP$1,0)),50) -> 0 | R5: =MROUND(R$3*INDEX('College Enrollment Projections'!$AJ$2:$AP$72,MATCH('Campus Enrol Disaggregation'!$O5,'College Enrollment Projections'!$AI$2:$AI$72,0),MATCH('Campus Enrol Disaggregation'!R$2,'College Enrollment Projections'!$AJ$1:$AP$1,0)),50) -> 9150 | S5: =MROUND(S$3*INDEX('College Enrollment Projections'!$AJ$2:$AP$72,MATCH('Campus Enrol Disaggregation'!$O5,'College Enrollment Projections'!$AI$2:$AI$72,0),MATCH('Campus Enrol Disaggregation'!S$2,'College Enrollment Projections'!$AJ$1:$AP$1,0)),50) -> 1800 | T5: =MROUND(T$3*INDEX('College Enrollment Projections'!$AJ$2:$AP$72,MATCH('Campus Enrol Disaggregation'!$O5,'College Enrollment Projections'!$AI$2:$AI$72,0),MATCH('Campus Enrol Disaggregation'!T$2,'College Enrollment Projections'!$AJ$1:$AP$1,0)),50) -> 200 | U5: =MROUND(U$3*INDEX('College Enrollment Projections'!$AJ$2:$AP$72,MATCH('Campus Enrol Disaggregation'!$O5,'College Enrollment Projections'!$AI$2:$AI$72,0),MATCH('Campus Enrol Disaggregation'!U$2,'College Enrollment Projections'!$AJ$1:$AP$1,0)),50) -> 1350 | V5: =MROUND(V$3*INDEX('College Enrollment Projections'!$AJ$2:$AP$72,MATCH('Campus Enrol Disaggregation'!$O5,'College Enrollment Projections'!$AI$2:$AI$72,0),MATCH('Campus Enrol Disaggregation'!V$2,'College Enrollment Projections'!$AJ$1:$AP$1,0)),50) -> 23550 | W5: =MROUND(INDEX('MAG College Enrollment Forecast'!$B$4:$H$74,MATCH($O5,'MAG College Enrollment Forecast'!$A$4:$A$74,0),MATCH(W$4,'MAG College Enrollment Forecast'!$B$1:$H$1,0)),50) -> 7900 | X5: =MROUND(INDEX('MAG College Enrollment Forecast'!$B$4:$H$74,MATCH($O5,'MAG College Enrollment Forecast'!$A$4:$A$74,0),MATCH(X$4,'MAG College Enrollment Forecast'!$B$1:$H$1,0)),50) -> 0 | Y5: =MROUND(INDEX('MAG College Enrollment Forecast'!$B$4:$H$74,MATCH($O5,'MAG College Enrollment Forecast'!$A$4:$A$74,0),MATCH(Y$4,'MAG College Enrollment Forecast'!$B$1:$H$1,0)),50) -> 0 | Z5: =MROUND(INDEX('MAG College Enrollment Forecast'!$B$4:$H$74,MATCH($O5,'MAG College Enrollment Forecast'!$A$4:$A$74,0),MATCH(Z$4,'MAG College Enrollment Forecast'!$B$1:$H$1,0)),50) -> 0 | AA5: =MROUND(AA$3*INDEX('College Enrollment Projections'!$AJ$2:$AP$72,MATCH('Campus Enrol Disaggregation'!$O5,'College Enrollment Projections'!$AI$2:$AI$72,0),MATCH('Campus Enrol Disaggregation'!AA$2,'College Enrollment Projections'!$AJ$1:$AP$1,0)),50) -> 10900 | AB5: =MROUND(AB$3*INDEX('College Enrollment Projections'!$AJ$2:$AP$72,MATCH('Campus Enrol Disaggregation'!$O5,'College Enrollment Projections'!$AI$2:$AI$72,0),MATCH('Campus Enrol Disaggregation'!AB$2,'College Enrollment Projections'!$AJ$1:$AP$1,0)),50) -> 2200 | AC5: =MROUND(AC$3*INDEX('College Enrollment Projections'!$AJ$2:$AP$72,MATCH('Campus Enrol Disaggregation'!$O5,'College Enrollment Projections'!$AI$2:$AI$72,0),MATCH('Campus Enrol Disaggregation'!AC$2,'College Enrollment Projections'!$AJ$1:$AP$1,0)),50) -> 0 | AD5: =SUM(P5:AC5) -> 87500
O6: 1991 | P6: =MROUND(P$3*INDEX('College Enrollment Projections'!$AJ$2:$AP$72,MATCH('Campus Enrol Disaggregation'!$O6,'College Enrollment Projections'!$AI$2:$AI$72,0),MATCH('Campus Enrol Disaggregation'!P$2,'College Enrollment Projections'!$AJ$1:$AP$1,0)),50) -> 31100 | Q6: =MROUND(Q$3*INDEX('College Enrollment Projections'!$AJ$2:$AP$72,MATCH('Campus Enrol Disaggregation'!$O6,'College Enrollment Projections'!$AI$2:$AI$72,0),MATCH('Campus Enrol Disaggregation'!Q$2,'College Enrollment Projections'!$AJ$1:$AP$1,0)),50) -> 0 | R6: =MROUND(R$3*INDEX('College Enrollment Projections'!$AJ$2:$AP$72,MATCH('Campus Enrol Disaggregation'!$O6,'College Enrollment Projections'!$AI$2:$AI$72,0),MATCH('Campus Enrol Disaggregation'!R$2,'College Enrollment Projections'!$AJ$1:$AP$1,0)),50) -> 10950 | S6: =MROUND(S$3*INDEX('College Enrollment Projections'!$AJ$2:$AP$72,MATCH('Campus Enrol Disaggregation'!$O6,'College Enrollment Projections'!$AI$2:$AI$72,0),MATCH('Campus Enrol Disaggregation'!S$2,'College Enrollment Projections'!$AJ$1:$AP$1,0)),50) -> 2150 | T6: =MROUND(T$3*INDEX('College Enrollment Projections'!$AJ$2:$AP$72,MATCH('Campus Enrol Disaggregation'!$O6,'College Enrollment Projections'!$AI$2:$AI$72,0),MATCH('Campus Enrol Disaggregation'!T$2,'College Enrollment Projections'!$AJ$1:$AP$1,0)),50) -> 250 | U6: =MROUND(U$3*INDEX('College Enrollment Projections'!$AJ$2:$AP$72,MATCH('Campus Enrol Disaggregation'!$O6,'College Enrollment Projections'!$AI$2:$AI$72,0),MATCH('Campus Enrol Disaggregation'!U$2,'College Enrollment Projections'!$AJ$1:$AP$1,0)),50) -> 1650 | V6: =MROUND(V$3*INDEX('College Enrollment Projections'!$AJ$2:$AP$72,MATCH('Campus Enrol Disaggregation'!$O6,'College Enrollment Projections'!$AI$2:$AI$72,0),MATCH('Campus Enrol Disaggregation'!V$2,'College Enrollment Projections'!$AJ$1:$AP$1,0)),50) -> 24750 | W6: =MROUND(INDEX('MAG College Enrollment Forecast'!$B$4:$H$74,MATCH($O6,'MAG College Enrollment Forecast'!$A$4:$A$74,0),MATCH(W$4,'MAG College Enrollment Forecast'!$B$1:$H$1,0)),50) -> 8800 | X6: =MROUND(INDEX('MAG College Enrollment Forecast'!$B$4:$H$74,MATCH($O6,'MAG College Enrollment Forecast'!$A$4:$A$74,0),MATCH(X$4,'MAG College Enrollment Forecast'!$B$1:$H$1,0)),50) -> 0 | Y6: =MROUND(INDEX('MAG College Enrollment Forecast'!$B$4:$H$74,MATCH($O6,'MAG College Enrollment Forecast'!$A$4:$A$74,0),MATCH(Y$4,'MAG College Enrollment Forecast'!$B$1:$H$1,0)),50) -> 0 | Z6: =MROUND(INDEX('MAG College Enrollment Forecast'!$B$4:$H$74,MATCH($O6,'MAG College Enrollment Forecast'!$A$4:$A$74,0),MATCH(Z$4,'MAG College Enrollment Forecast'!$B$1:$H$1,0)),50) -> 0 | AA6: =MROUND(AA$3*INDEX('College Enrollment Projections'!$AJ$2:$AP$72,MATCH('Campus Enrol Disaggregation'!$O6,'College Enrollment Projections'!$AI$2:$AI$72,0),MATCH('Campus Enrol Disaggregation'!AA$2,'College Enrollment Projections'!$AJ$1:$AP$1,0)),50) -> 11750 | AB6: =MROUND(AB$3*INDEX('College Enrollment Projections'!$AJ$2:$AP$72,MATCH('Campus Enrol Disaggregation'!$O6,'College Enrollment Projections'!$AI$2:$AI$72,0),MATCH('Campus Enrol Disaggregation'!AB$2,'College Enrollment Projections'!$AJ$1:$AP$1,0)),50) -> 2350 | AC6: =MROUND(AC$3*INDEX('College Enrollment Projections'!$AJ$2:$AP$72,MATCH('Campus Enrol Disaggregation'!$O6,'College Enrollment Projections'!$AI$2:$AI$72,0),MATCH('Campus Enrol Disaggregation'!AC$2,'College Enrollment Projections'!$AJ$1:$AP$1,0)),50) -> 0 | AD6: =SUM(P6:AC6) -> 93750
O7: 1992 | P7: =MROUND(P$3*INDEX('College Enrollment Projections'!$AJ$2:$AP$72,MATCH('Campus Enrol Disaggregation'!$O7,'College Enrollment Projections'!$AI$2:$AI$72,0),MATCH('Campus Enrol Disaggregation'!P$2,'College Enrollment Projections'!$AJ$1:$AP$1,0)),50) -> 31100 | Q7: =MROUND(Q$3*INDEX('College Enrollment Projections'!$AJ$2:$AP$72,MATCH('Campus Enrol Disaggregation'!$O7,'College Enrollment Projections'!$AI$2:$AI$72,0),MATCH('Campus Enrol Disaggregation'!Q$2,'College Enrollment Projections'!$AJ$1:$AP$1,0)),50) -> 0 | R7: =MROUND(R$3*INDEX('College Enrollment Projections'!$AJ$2:$AP$72,MATCH('Campus Enrol Disaggregation'!$O7,'College Enrollment Projections'!$AI$2:$AI$72,0),MATCH('Campus Enrol Disaggregation'!R$2,'College Enrollment Projections'!$AJ$1:$AP$1,0)),50) -> 12150 | S7: =MROUND(S$3*INDEX('College Enrollment Projections'!$AJ$2:$AP$72,MATCH('Campus Enrol Disaggregation'!$O7,'College Enrollment Projections'!$AI$2:$AI$72,0),MATCH('Campus Enrol Disaggregation'!S$2,'College Enrollment Projections'!$AJ$1:$AP$1,0)),50) -> 2350 | T7: =MROUND(T$3*INDEX('College Enrollment Projections'!$AJ$2:$AP$72,MATCH('Campus Enrol Disaggregation'!$O7,'College Enrollment Projections'!$AI$2:$AI$72,0),MATCH('Campus Enrol Disaggregation'!T$2,'College Enrollment Projections'!$AJ$1:$AP$1,0)),50) -> 300 | U7: =MROUND(U$3*INDEX('College Enrollment Projections'!$AJ$2:$AP$72,MATCH('Campus Enrol Disaggregation'!$O7,'College Enrollment Projections'!$AI$2:$AI$72,0),MATCH('Campus Enrol Disaggregation'!U$2,'College Enrollment Projections'!$AJ$1:$AP$1,0)),50) -> 1800 | V7: =MROUND(V$3*INDEX('College Enrollment Projections'!$AJ$2:$AP$72,MATCH('Campus Enrol Disaggregation'!$O7,'College Enrollment Projections'!$AI$2:$AI$72,0),MATCH('Campus Enrol Disaggregation'!V$2,'College Enrollment Projections'!$AJ$1:$AP$1,0)),50) -> 25050 | W7: =MROUND(INDEX('MAG College Enrollment Forecast'!$B$4:$H$74,MATCH($O7,'MAG College Enrollment Forecast'!$A$4:$A$74,0),MATCH(W$4,'MAG College Enrollment Forecast'!$B$1:$H$1,0)),50) -> 9600 | X7: =MROUND(INDEX('MAG College Enrollment Forecast'!$B$4:$H$74,MATCH($O7,'MAG College Enrollment Forecast'!$A$4:$A$74,0),MATCH(X$4,'MAG College Enrollment Forecast'!$B$1:$H$1,0)),50) -> 0 | Y7: =MROUND(INDEX('MAG College Enrollment Forecast'!$B$4:$H$74,MATCH($O7,'MAG College Enrollment Forecast'!$A$4:$A$74,0),MATCH(Y$4,'MAG College Enrollment Forecast'!$B$1:$H$1,0)),50) -> 0 | Z7: =MROUND(INDEX('MAG College Enrollment Forecast'!$B$4:$H$74,MATCH($O7,'MAG College Enrollment Forecast'!$A$4:$A$74,0),MATCH(Z$4,'MAG College Enrollment Forecast'!$B$1:$H$1,0)),50) -> 0 | AA7: =MROUND(AA$3*INDEX('College Enrollment Projections'!$AJ$2:$AP$72,MATCH('Campus Enrol Disaggregation'!$O7,'College Enrollment Projections'!$AI$2:$AI$72,0),MATCH('Campus Enrol Disaggregation'!AA$2,'College Enrollment Projections'!$AJ$1:$AP$1,0)),50) -> 12150 | AB7: =MROUND(AB$3*INDEX('College Enrollment Projections'!$AJ$2:$AP$72,MATCH('Campus Enrol Disaggregation'!$O7,'College Enrollment Projections'!$AI$2:$AI$72,0),MATCH('Campus Enrol Disaggregation'!AB$2,'College Enrollment Projections'!$AJ$1:$AP$1,0)),50) -> 2450 | AC7: =MROUND(AC$3*INDEX('College Enrollment Projections'!$AJ$2:$AP$72,MATCH('Campus Enrol Disaggregation'!$O7,'College Enrollment Projections'!$AI$2:$AI$72,0),MATCH('Campus Enrol Disaggregation'!AC$2,'College Enrollment Projections'!$AJ$1:$AP$1,0)),50) -> 0 | AD7: =SUM(P7:AC7) -> 96950
O8: 1993 | P8: =MROUND(P$3*INDEX('College Enrollment Projections'!$AJ$2:$AP$72,MATCH('Campus Enrol Disaggregation'!$O8,'College Enrollment Projections'!$AI$2:$AI$72,0),MATCH('Campus Enrol Disaggregation'!P$2,'College Enrollment Projections'!$AJ$1:$AP$1,0)),50) -> 30550 | Q8: =MROUND(Q$3*INDEX('College Enrollment Projections'!$AJ$2:$AP$72,MATCH('Campus Enrol Disaggregation'!$O8,'College Enrollment Projections'!$AI$2:$AI$72,0),MATCH('Campus Enrol Disaggregation'!Q$2,'College Enrollment Projections'!$AJ$1:$AP$1,0)),50) -> 0 | R8: =MROUND(R$3*INDEX('College Enrollment Projections'!$AJ$2:$AP$72,MATCH('Campus Enrol Disaggregation'!$O8,'College Enrollment Projections'!$AI$2:$AI$72,0),MATCH('Campus Enrol Disaggregation'!R$2,'College Enrollment Projections'!$AJ$1:$AP$1,0)),50) -> 12550 | S8: =MROUND(S$3*INDEX('College Enrollment Projections'!$AJ$2:$AP$72,MATCH('Campus Enrol Disaggregation'!$O8,'College Enrollment Projections'!$AI$2:$AI$72,0),MATCH('Campus Enrol Disaggregation'!S$2,'College Enrollment Projections'!$AJ$1:$AP$1,0)),50) -> 2450 | T8: =MROUND(T$3*INDEX('College Enrollment Projections'!$AJ$2:$AP$72,MATCH('Campus Enrol Disaggregation'!$O8,'College Enrollment Projections'!$AI$2:$AI$72,0),MATCH('Campus Enrol Disaggregation'!T$2,'College Enrollment Projections'!$AJ$1:$AP$1,0)),50) -> 300 | U8: =MROUND(U$3*INDEX('College Enrollment Projections'!$AJ$2:$AP$72,MATCH('Campus Enrol Disaggregation'!$O8,'College Enrollment Projections'!$AI$2:$AI$72,0),MATCH('Campus Enrol Disaggregation'!U$2,'College Enrollment Projections'!$AJ$1:$AP$1,0)),50) -> 1850 | V8: =MROUND(V$3*INDEX('College Enrollment Projections'!$AJ$2:$AP$72,MATCH('Campus Enrol Disaggregation'!$O8,'College Enrollment Projections'!$AI$2:$AI$72,0),MATCH('Campus Enrol Disaggregation'!V$2,'College Enrollment Projections'!$AJ$1:$AP$1,0)),50) -> 25150 | W8: =MROUND(INDEX('MAG College Enrollment Forecast'!$B$4:$H$74,MATCH($O8,'MAG College Enrollment Forecast'!$A$4:$A$74,0),MATCH(W$4,'MAG College Enrollment Forecast'!$B$1:$H$1,0)),50) -> 10500 | X8: =MROUND(INDEX('MAG College Enrollment Forecast'!$B$4:$H$74,MATCH($O8,'MAG College Enrollment Forecast'!$A$4:$A$74,0),MATCH(X$4,'MAG College Enrollment Forecast'!$B$1:$H$1,0)),50) -> 0 | Y8: =MROUND(INDEX('MAG College Enrollment Forecast'!$B$4:$H$74,MATCH($O8,'MAG College Enrollment Forecast'!$A$4:$A$74,0),MATCH(Y$4,'MAG College Enrollment Forecast'!$B$1:$H$1,0)),50) -> 0 | Z8: =MROUND(INDEX('MAG College Enrollment Forecast'!$B$4:$H$74,MATCH($O8,'MAG College Enrollment Forecast'!$A$4:$A$74,0),MATCH(Z$4,'MAG College Enrollment Forecast'!$B$1:$H$1,0)),50) -> 0 | AA8: =MROUND(AA$3*INDEX('College Enrollment Projections'!$AJ$2:$AP$72,MATCH('Campus Enrol Disaggregation'!$O8,'College Enrollment Projections'!$AI$2:$AI$72,0),MATCH('Campus Enrol Disaggregation'!AA$2,'College Enrollment Projections'!$AJ$1:$AP$1,0)),50) -> 11700 | AB8: =MROUND(AB$3*INDEX('College Enrollment Projections'!$AJ$2:$AP$72,MATCH('Campus Enrol Disaggregation'!$O8,'College Enrollment Projections'!$AI$2:$AI$72,0),MATCH('Campus Enrol Disaggregation'!AB$2,'College Enrollment Projections'!$AJ$1:$AP$1,0)),50) -> 2350 | AC8: =MROUND(AC$3*INDEX('College Enrollment Projections'!$AJ$2:$AP$72,MATCH('Campus Enrol Disaggregation'!$O8,'College Enrollment Projections'!$AI$2:$AI$72,0),MATCH('Campus Enrol Disaggregation'!AC$2,'College Enrollment Projections'!$AJ$1:$AP$1,0)),50) -> 0 | AD8: =SUM(P8:AC8) -> 97400
O9: 1994 | P9: =MROUND(P$3*INDEX('College Enrollment Projections'!$AJ$2:$AP$72,MATCH('Campus Enrol Disaggregation'!$O9,'College Enrollment Projections'!$AI$2:$AI$72,0),MATCH('Campus Enrol Disaggregation'!P$2,'College Enrollment Projections'!$AJ$1:$AP$1,0)),50) -> 30400 | Q9: =MROUND(Q$3*INDEX('College Enrollment Projections'!$AJ$2:$AP$72,MATCH('Campus Enrol Disaggregation'!$O9,'College Enrollment Projections'!$AI$2:$AI$72,0),MATCH('Campus Enrol Disaggregation'!Q$2,'College Enrollment Projections'!$AJ$1:$AP$1,0)),50) -> 0 | R9: =MROUND(R$3*INDEX('College Enrollment Projections'!$AJ$2:$AP$72,MATCH('Campus Enrol Disaggregation'!$O9,'College Enrollment Projections'!$AI$2:$AI$72,0),MATCH('Campus Enrol Disaggregation'!R$2,'College Enrollment Projections'!$AJ$1:$AP$1,0)),50) -> 13300 | S9: =MROUND(S$3*INDEX('College Enrollment Projections'!$AJ$2:$AP$72,MATCH('Campus Enrol Disaggregation'!$O9,'College Enrollment Projections'!$AI$2:$AI$72,0),MATCH('Campus Enrol Disaggregation'!S$2,'College Enrollment Projections'!$AJ$1:$AP$1,0)),50) -> 2600 | T9: =MROUND(T$3*INDEX('College Enrollment Projections'!$AJ$2:$AP$72,MATCH('Campus Enrol Disaggregation'!$O9,'College Enrollment Projections'!$AI$2:$AI$72,0),MATCH('Campus Enrol Disaggregation'!T$2,'College Enrollment Projections'!$AJ$1:$AP$1,0)),50) -> 300 | U9: =MROUND(U$3*INDEX('College Enrollment Projections'!$AJ$2:$AP$72,MATCH('Campus Enrol Disaggregation'!$O9,'College Enrollment Projections'!$AI$2:$AI$72,0),MATCH('Campus Enrol Disaggregation'!U$2,'College Enrollment Projections'!$AJ$1:$AP$1,0)),50) -> 2000 | V9: =MROUND(V$3*INDEX('College Enrollment Projections'!$AJ$2:$AP$72,MATCH('Campus Enrol Disaggregation'!$O9,'College Enrollment Projections'!$AI$2:$AI$72,0),MATCH('Campus Enrol Disaggregation'!V$2,'College Enrollment Projections'!$AJ$1:$AP$1,0)),50) -> 24850 | W9: =MROUND(INDEX('MAG College Enrollment Forecast'!$B$4:$H$74,MATCH($O9,'MAG College Enrollment Forecast'!$A$4:$A$74,0),MATCH(W$4,'MAG College Enrollment Forecast'!$B$1:$H$1,0)),50) -> 13300 | X9: =MROUND(INDEX('MAG College Enrollment Forecast'!$B$4:$H$74,MATCH($O9,'MAG College Enrollment Forecast'!$A$4:$A$74,0),MATCH(X$4,'MAG College Enrollment Forecast'!$B$1:$H$1,0)),50) -> 0 | Y9: =MROUND(INDEX('MAG College Enrollment Forecast'!$B$4:$H$74,MATCH($O9,'MAG College Enrollment Forecast'!$A$4:$A$74,0),MATCH(Y$4,'MAG College Enrollment Forecast'!$B$1:$H$1,0)),50) -> 0 | Z9: =MROUND(INDEX('MAG College Enrollment Forecast'!$B$4:$H$74,MATCH($O9,'MAG College Enrollment Forecast'!$A$4:$A$74,0),MATCH(Z$4,'MAG College Enrollment Forecast'!$B$1:$H$1,0)),50) -> 0 | AA9: =MROUND(AA$3*INDEX('College Enrollment Projections'!$AJ$2:$AP$72,MATCH('Campus Enrol Disaggregation'!$O9,'College Enrollment Projections'!$AI$2:$AI$72,0),MATCH('Campus Enrol Disaggregation'!AA$2,'College Enrollment Projections'!$AJ$1:$AP$1,0)),50) -> 11550 | AB9: =MROUND(AB$3*INDEX('College Enrollment Projections'!$AJ$2:$AP$72,MATCH('Campus Enrol Disaggregation'!$O9,'College Enrollment Projections'!$AI$2:$AI$72,0),MATCH('Campus Enrol Disaggregation'!AB$2,'College Enrollment Projections'!$AJ$1:$AP$1,0)),50) -> 2300 | AC9: =MROUND(AC$3*INDEX('College Enrollment Projections'!$AJ$2:$AP$72,MATCH('Campus Enrol Disaggregation'!$O9,'College Enrollment Projections'!$AI$2:$AI$72,0),MATCH('Campus Enrol Disaggregation'!AC$2,'College Enrollment Projections'!$AJ$1:$AP$1,0)),50) -> 0 | AD9: =SUM(P9:AC9) -> 100600
