Workbook

Sheet Export_ControlTot
A1: Trip Table Control Total
D2: =(D45/D5)^(1/35)-1 -> 0.033326208 | E2: =(E45/E5)^(1/35)-1 -> 0.0025636279 | F2: =(F45/F5)^(1/35)-1 -> 0.0083149749 | G2: =(G45/G5)^(1/35)-1 -> 0.0083149749 | H2: =(H45/H5)^(1/35)-1 -> 0.010894515 | I2: =(I45/I5)^(1/35)-1 -> 0.029652837 | J2: =(J45/J5)^(1/35)-1 -> 0.03514702 | K2: =(K45/K5)^(1/35)-1 -> 0.015415105 | ... S2: =(S45/S5)^(1/35)-1 -> 0.015409768 | T2: =(T45/T19)^(1/35)-1 -> 0.081576934 | U2: =(U45/U5)^(1/35)-1 -> 0.00089927024 | V2: =(V45/V5)^(1/35)-1 -> 0.019195821 | W2: =(W45/W10)^(1/35)-1 -> 0.019569946 | X2: =(X45/X5)^(1/35)-1 -> 0.014919234 | Y2: =(Y45/Y18)^(1/35)-1 -> 0.062602895 | Z2: =(Z45/Z28)^(1/35)-1 -> 0.05036397
A4: ;Year | B4: Airport | C4: Lagoon | D4: LDSBC | E4: Westmin | F4: UofU_Main | G4: UofU_Med | H4: WSU_Ogden | I4: WSU_Davis | J4: WSU_West | K4: SLCC_TL | L4: SLCC_SC | M4: SLCC_JD | N4: SLCC_Mead | O4: SLCC_ML | P4: SLCC_LB | Q4: SLCC_HL | R4: SLCC_Airp | S4: SLCC_West | T4: SLCC_HM | U4: BYU | V4: UVU_main | W4: UVU_Geneva | X4: UVU_ThankP | Y4: UVU_VINE | Z4: UVU_PAYSON
A5: 2010 | B5: =airport2019!G7 -> 26389.105 | C5: =lagoon2019!E13 -> 6424.3697 | D5: =Result!B5 -> 2000 | E5: =Result!C5 -> 3200 | F5: =Result!D5 -> 26896.55 | G5: =Result!E5 -> 4746.45 | H5: =Result!F5 -> 19352 | I5: =Result!G5 -> 4409 | J5: =Result!H5 -> 735 | K5: =Result!I5 -> 18914 | ... Z5: =Result!X5 -> 0
A6: 2011 | B6: =airport2019!G8 -> 25742.608 | C6: =lagoon2019!E14 -> 6505.2521 | D6: =Result!B6 -> 2100 | E6: =Result!C6 -> 3207.5 | F6: =Result!D6 -> 27813.7 | G6: =Result!E6 -> 4908.3 | H6: =Result!F6 -> 20742 | I6: =Result!G6 -> 4726 | J6: =Result!H6 -> 788 | K6: =Result!I6 -> 18170 | ... Z6: =Result!X6 -> 0
A7: 2012 | B7: =airport2019!G9 -> 25379.758 | C7: =lagoon2019!E15 -> 6595.3782 | D7: =Result!B7 -> 2200 | E7: =Result!C7 -> 3215 | F7: =Result!D7 -> 28297.35 | G7: =Result!E7 -> 4993.65 | H7: =Result!F7 -> 21248.25 | I7: =Result!G7 -> 5232.25 | J7: =Result!H7 -> 900.5 | K7: =Result!I7 -> 17687 | ... Z7: =Result!X7 -> 0
A8: 2013 | B8: =airport2019!G10 -> 25486.312 | C8: =lagoon2019!E16 -> 6701.6807 | D8: =Result!B8 -> 2307.8947 | E8: =Result!C8 -> 3222.5 | F8: =Result!D8 -> 30792.1 | G8: =Result!E8 -> 5433.9 | H8: =Result!F8 -> 20575.5 | I8: =Result!G8 -> 4559.5 | J8: =Result!H8 -> 751 | K8: =Result!I8 -> 17311 | ... Z8: =Result!X8 -> 0
A9: 2014 | B9: =airport2019!G11 -> 26692.213 | C9: =lagoon2019!E17 -> 6791.8067 | D9: =Result!B9 -> 2415.7895 | E9: =Result!C9 -> 3230 | F9: =Result!D9 -> 27202.55 | G9: =Result!E9 -> 4800.45 | H9: =Result!F9 -> 21037.65 | I9: =Result!G9 -> 5021.65 | J9: =Result!H9 -> 853.7 | K9: =Result!I9 -> 16525 | ... Z9: =Result!X9 -> 0
A10: 2015 | B10: =airport2019!G12 -> 27954.02 | C10: =lagoon2019!E18 -> 6898.1092 | D10: =Result!B10 -> 2523.6842 | E10: =Result!C10 -> 3237.5 | F10: =Result!D10 -> 27331.75 | G10: =Result!E10 -> 4823.25 | H10: =Result!F10 -> 20740.2 | I10: =Result!G10 -> 4724.2 | J10: =Result!H10 -> 787.6 | K10: =Result!I10 -> 15379 | ... Z10: =Result!X10 -> 0
A11: 2016 | B11: =airport2019!G13 -> 29234.872 | C11: =lagoon2019!E19 -> 7034.4538 | D11: =Result!B11 -> 2631.5789 | E11: =Result!C11 -> 3245 | F11: =Result!D11 -> 27583.35 | G11: =Result!E11 -> 4867.65 | H11: =Result!F11 -> 21183 | I11: =Result!G11 -> 5167 | J11: =Result!H11 -> 886 | K11: =Result!I11 -> 15874 | ... Z11: =Result!X11 -> 0
A12: 2017 | B12: =airport2019!G14 -> 30552.746 | C12: =lagoon2019!E20 -> 7168.4874 | D12: =Result!B12 -> 2739.4737 | E12: =Result!C12 -> 3252.5 | F12: =Result!D12 -> 28180.05 | G12: =Result!E12 -> 4972.95 | H12: =Result!F12 -> 21697.35 | I12: =Result!G12 -> 5681.35 | J12: =Result!H12 -> 1000.3 | K12: =Result!I12 -> 15945 | ... Z12: =Result!X12 -> 0
A13: 2018 | B13: =airport2019!G15 -> 32263.358 | C13: =lagoon2019!E21 -> 7300.2101 | D13: =Result!B13 -> 2847.3684 | E13: =Result!C13 -> 3260 | F13: =Result!D13 -> 29109.95 | G13: =Result!E13 -> 5137.05 | H13: =Result!F13 -> 22755.251 | I13: =Result!G13 -> 6739.251 | J13: =Result!H13 -> 1235.3891 | K13: =Result!I13 -> 16295 | ... Z13: =Result!X13 -> 0
A14: 2019 | B14: =airport2019!G16 -> 32699.509 | C14: =lagoon2019!E22 -> 7434.2437 | D14: =Result!B14 -> 2955.2632 | E14: =Result!C14 -> 3267.5 | F14: =Result!D14 -> 29959.1 | G14: =Result!E14 -> 5286.9 | H14: =Result!F14 -> 23382.042 | I14: =Result!G14 -> 7366.0424 | J14: =Result!H14 -> 1374.6761 | K14: =Result!I14 -> 16627 | ... Z14: =Result!X14 -> 0
A15: 2020 | B15: =airport2019!G17 -> 33141.556 | C15: =lagoon2019!E23 -> 7565.9664 | D15: =Result!B15 -> 3063.1579 | E15: =Result!C15 -> 3275 | F15: =Result!D15 -> 30666.3 | G15: =Result!E15 -> 5411.7 | H15: =Result!F15 -> 24004.267 | I15: =Result!G15 -> 7988.2666 | J15: =Result!H15 -> 1512.9481 | K15: =Result!I15 -> 16968 | ... Z15: =Result!X15 -> 0
A16: 2021 | B16: =airport2019!G18 -> 33589.579 | C16: =lagoon2019!E24 -> 7717.4033 | D16: =Result!B16 -> 3171.0526 | E16: =Result!C16 -> 3282.5 | F16: =Result!D16 -> 30990.15 | G16: =Result!E16 -> 5468.85 | H16: =Result!F16 -> 24610.161 | I16: =Result!G16 -> 8594.1612 | J16: =Result!H16 -> 1647.5914 | K16: =Result!I16 -> 17316 | ... Z16: =Result!X16 -> 0
... A45: 2050 | B45: =airport2019!G47 -> 49581.873 | C45: =lagoon2019!E53 -> 11590.238 | D45: =Result!B45 -> 6300 | E45: =Result!C45 -> 3500 | F45: =Result!D45 -> 35938.85 | G45: =Result!E45 -> 6342.15 | H45: =Result!F45 -> 28276.8 | I45: =Result!G45 -> 12260.8 | J45: =Result!H45 -> 2462.4 | K45: =Result!I45 -> 32308 | ... Z45: =Result!X45 -> 1675

Sheet Export_Factors
A1: College Factors
B3: ;index | C3: LDSBC | D3: Westmin | E3: UofU_Main | F3: UofU_Med | G3: WSU_Ogden | H3: WSU_Davis | I3: WSU_West | J3: SLCC_TL | K3: SLCC_SC | L3: SLCC_JD | M3: SLCC_Mead | N3: SLCC_ML | O3: SLCC_LB | P3: SLCC_HL | Q3: SLCC_Airp | R3: SLCC_West | S3: SLCC_HM | T3: BYU | U3: UVU_main | V3: UVU_Geneva | W3: UVU_ThankP | X3: UVU_VINE | Y3: UVU_PAYSON | Z3: Var_Name
A4: Pct_Remove | B4: 1 | C4: ='calc%concurrent'!F5 -> 0.1005 | D4: ='calc%concurrent'!F12 -> 0.0115625 | E4: ='calc%concurrent'!F9 -> 0.026040514 | F4: =$E4 -> 0.026040514 | G4: ='calc%concurrent'!F10 -> 0.21501654 | H4: ='calc%concurrent'!F11 -> 0.30851477 | I4: =H4 -> 0.30851477 | J4: ='calc%concurrent'!F6 -> 0.34092451 | K4: =$J4 -> 0.34092451 | L4: =$J4 -> 0.34092451 | M4: =$J4 -> 0.34092451 | N4: =$J4 -> 0.34092451 | O4: =$J4 -> 0.34092451 | P4: =$J4 -> 0.34092451 | Q4: =$J4 -> 0.34092451 | R4: =$J4 -> 0.34092451 | S4: =$J4 -> 0.34092451 | T4: =E4 -> 0.026040514 | U4: ='calc%concurrent'!F8 -> 0.26992029 | V4: =$U4 -> 0.26992029 | W4: =$U4 -> 0.26992029 | X4: =$U4 -> 0.26992029 | Y4: =$U4 -> 0.26992029 | Z4: Pct_Remove
A5: FTERate | B5: 2 | C5: ='Calc%FTE'!F43 -> 1.1790281 | D5: ='Calc%FTE'!F47 -> 1.0984237 | E5: ='Calc%FTE'!E31 -> 1.2097574 | F5: =$E5 -> 1.2097574 | G5: ='Calc%FTE'!E33 -> 1.5884046 | H5: =$G5 -> 1.5884046 | I5: =$G5 -> 1.5884046 | J5: ='Calc%FTE'!E38 -> 2.005139 | K5: =$J5 -> 2.005139 | L5: =$J5 -> 2.005139 | M5: =$J5 -> 2.005139 | N5: =$J5 -> 2.005139 | O5: =$J5 -> 2.005139 | P5: =$J5 -> 2.005139 | Q5: =$J5 -> 2.005139 | R5: =$J5 -> 2.005139 | S5: =$J5 -> 2.005139 | T5: =E5 -> 1.2097574 | U5: ='Calc%FTE'!E37 -> 1.3995716 | V5: =$U5 -> 1.3995716 | W5: =$U5 -> 1.3995716 | X5: =$U5 -> 1.3995716 | Y5: =$U5 -> 1.3995716 | Z5: FTERate
A6: HBCRates | B6: 3 | C6: 0.9301 | D6: 0.9301 | E6: 0.9301 | F6: =$E6 -> 0.9301 | G6: 0.83 | H6: 0.677 | I6: =H6 -> 0.677 | J6: 0.6219 | K6: 0.6422 | L6: 0.5687 | M6: =L6 -> 0.5687 | N6: 0.6158 | O6: =N6 -> 0.6158 | P6: =O6 -> 0.6158 | Q6: =P6 -> 0.6158 | R6: =Q6 -> 0.6158 | S6: =R6 -> 0.6158 | T6: 0.9301 | U6: 0.9452 | V6: =$U6 -> 0.9452 | W6: =$U6 -> 0.9452 | X6: =$U6 -> 0.9452 | Y6: =$U6 -> 0.9452 | Z6: HBCRates
A8: Note:
A9: Removal means concurrent, online degree etc.
A10: FTERate = FTE / Total Headcount, Total Headcount includes online and concurrent enrollment

Sheet Result
D2: 0.85 | E2: 0.15
D3: U of U | F3: WSU Ogden | I3: SLCC | T3: UVU
A4: Year | B4: LDSBC | C4: Westmintor | D4: Main | E4: Med | F4: Ogden | G4: Davis | H4: west | I4: =M47 -> Taylorsville Redwood Campus | J4: =N47 -> South City Campus | K4: =O47 -> Jordan Campus | L4: =P47 -> Meadowbrook | M4: =Q47 -> Miller Campus & Miller Campus (Internet) | N4: =R47 -> Library Square Center (Opened Spring 06-07) | O4: =S47 -> highland | P4: =T47 -> Ariport | Q4: =U47 -> Westpointe | R4: Heriman | S4: BYU | T4: main | U4: Geneva | V4: thankPoint | W4: vineyard | X4: payson
A5: 2010 | B5: =B6-100 -> 2000 | C5: =Westminstor!B24 -> 3200 | D5: =U!$F42 * D$2 -> 26896.55 | E5: =U!$F42 * E$2 -> 4746.45 | F5: =ROUND(WSU!F123*0.79,0) -> 19352 | G5: =ROUND(WSU!F123*0.18,0) -> 4409 | H5: =ROUND(WSU!F123*0.03,0) -> 735 | I5: =ROUND(slcc!$C24*M$48,0) -> 18914 | J5: =ROUND(slcc!$C24*N$48,0) -> 6394 | K5: =ROUND(slcc!$C24*O$48,0) -> 7160 | L5: =ROUND(slcc!$C24*P$48,0) -> 268 | M5: =ROUND(slcc!$C24*Q$48,0) -> 2718 | N5: =ROUND(slcc!$C24*R$48,0) -> 1187 | O5: =ROUND(slcc!$C24*S$48,0) -> 1072 | P5: 200 | Q5: =ROUND(slcc!$C24*U$48,0) -> 421 | S5: =BYU!E6 -> 32947 | T5: =ROUND(UVU!C24-V5-U5,0) -> 31340 | V5: 399
A6: 2011 | B6: =B7-100 -> 2100 | C6: =Westminstor!B25 -> 3207.5 | D6: =U!$F43 * D$2 -> 27813.7 | E6: =U!$F43 * E$2 -> 4908.3 | F6: =ROUND(WSU!F124*0.79,0) -> 20742 | G6: =ROUND(WSU!F124*0.18,0) -> 4726 | H6: =ROUND(WSU!F124*0.03,0) -> 788 | I6: =ROUND(slcc!$C25*M$48,0) -> 18170 | J6: =ROUND(slcc!$C25*N$48,0) -> 6143 | K6: =ROUND(slcc!$C25*O$48,0) -> 6878 | L6: =ROUND(slcc!$C25*P$48,0) -> 257 | M6: =ROUND(slcc!$C25*Q$48,0) -> 2612 | N6: =ROUND(slcc!$C25*R$48,0) -> 1140 | O6: =ROUND(slcc!$C25*S$48,0) -> 1030 | P6: =P5+20 -> 220 | Q6: =ROUND(slcc!$C25*U$48,0) -> 405 | S6: =ROUND(S$5+(S$45-S$5)*($A6-$A$5)/($A$45-$A$5),0) -> 32973 | T6: =UVU!C25-SUM(U6:X6) -> 32334 | V6: 400
A7: 2012 | B7: =LDSBC!B3 -> 2200 | C7: =Westminstor!B26 -> 3215 | D7: =U!$F44 * D$2 -> 28297.35 | E7: =U!$F44 * E$2 -> 4993.65 | F7: =F6+0.45*(WSU!F125-WSU!F124) -> 21248.25 | G7: =G6+0.45*(WSU!F125-WSU!F124) -> 5232.25 | H7: =H6+0.1*(WSU!F125-WSU!F124) -> 900.5 | I7: =ROUND(slcc!$C26*M$48,0) -> 17687 | J7: =ROUND(slcc!$C26*N$48,0) -> 5979 | K7: =ROUND(slcc!$C26*O$48,0) -> 6695 | L7: =ROUND(slcc!$C26*P$48,0) -> 251 | M7: =ROUND(slcc!$C26*Q$48,0) -> 2542 | N7: =ROUND(slcc!$C26*R$48,0) -> 1110 | O7: =ROUND(slcc!$C26*S$48,0) -> 1003 | P7: =P6+20 -> 240 | Q7: =ROUND(slcc!$C26*U$48,0) -> 394 | S7: =ROUND(S$5+(S$45-S$5)*($A7-$A$5)/($A$45-$A$5),0) -> 33000 | T7: =UVU!C26-SUM(U7:X7) -> 31403 | V7: =ROUND(V$6+(V$45-V$6)*($A7-$A$6)/($A$45-$A$6),0) -> 407
A8: 2013 | B8: =LDSBC!B4 -> 2307.8947 | C8: =Westminstor!B27 -> 3222.5 | D8: =U!$F45 * D$2 -> 30792.1 | E8: =U!$F45 * E$2 -> 5433.9 | F8: =F7+0.45*(WSU!F126-WSU!F125) -> 20575.5 | G8: =G7+0.45*(WSU!F126-WSU!F125) -> 4559.5 | H8: =H7+0.1*(WSU!F126-WSU!F125) -> 751 | I8: =ROUND(slcc!$C27*M$48,0) -> 17311 | J8: =ROUND(slcc!$C27*N$48,0) -> 5852 | K8: =ROUND(slcc!$C27*O$48,0) -> 6553 | L8: =ROUND(slcc!$C27*P$48,0) -> 245 | M8: =ROUND(slcc!$C27*Q$48,0) -> 2488 | N8: =ROUND(slcc!$C27*R$48,0) -> 1086 | O8: =ROUND(slcc!$C27*S$48,0) -> 981 | P8: =P7+20 -> 260 | Q8: =ROUND(slcc!$C27*U$48,0) -> 385 | S8: =ROUND(S$5+(S$45-S$5)*($A8-$A$5)/($A$45-$A$5),0) -> 33026 | T8: =UVU!C27-SUM(U8:X8) -> 30466 | V8: =ROUND(V$6+(V$45-V$6)*($A8-$A$6)/($A$45-$A$6),0) -> 414
A9: 2014 | B9: =LDSBC!B5 -> 2415.7895 | C9: =Westminstor!B28 -> 3230 | D9: =U!$F46 * D$2 -> 27202.55 | E9: =U!$F46 * E$2 -> 4800.45 | F9: =F8+0.45*(WSU!F127-WSU!F126) -> 21037.65 | G9: =G8+0.45*(WSU!F127-WSU!F126) -> 5021.65 | H9: =H8+0.1*(WSU!F127-WSU!F126) -> 853.7 | I9: =ROUND(slcc!$C28*M$48,0) -> 16525 | J9: =ROUND(slcc!$C28*N$48,0) -> 5586 | K9: =ROUND(slcc!$C28*O$48,0) -> 6255 | L9: =ROUND(slcc!$C28*P$48,0) -> 234 | M9: =ROUND(slcc!$C28*Q$48,0) -> 2375 | N9: =ROUND(slcc!$C28*R$48,0) -> 1037 | O9: =ROUND(slcc!$C28*S$48,0) -> 937 | P9: =P8+20 -> 280 | Q9: =ROUND(slcc!$C28*U$48,0) -> 368 | S9: =ROUND(S$5+(S$45-S$5)*($A9-$A$5)/($A$45-$A$5),0) -> 33052 | T9: =UVU!C28-SUM(U9:X9) -> 31168 | V9: =ROUND(V$6+(V$45-V$6)*($A9-$A$6)/($A$45-$A$6),0) -> 421
A10: 2015 | B10: =LDSBC!B6 -> 2523.6842 | C10: =Westminstor!B29 -> 3237.5 | D10: =U!$F47 * D$2 -> 27331.75 | E10: =U!$F47 * E$2 -> 4823.25 | F10: =F9+0.45*(WSU!F128-WSU!F127) -> 20740.2 | G10: =G9+0.45*(WSU!F128-WSU!F127) -> 4724.2 | H10: =H9+0.1*(WSU!F128-WSU!F127) -> 787.6 | I10: =ROUND(slcc!$C29*M$48,0) -> 15379 | J10: =ROUND(slcc!$C29*N$48,0) -> 5199 | K10: =ROUND(slcc!$C29*O$48,0) -> 5821 | L10: =ROUND(slcc!$C29*P$48,0) -> 218 | M10: =ROUND(slcc!$C29*Q$48,0) -> 2210 | N10: =ROUND(slcc!$C29*R$48,0) -> 965 | O10: =ROUND(slcc!$C29*S$48,0) -> 872 | P10: =P9+20 -> 300 | Q10: =ROUND(slcc!$C29*U$48,0) -> 342 | S10: =ROUND(S$5+(S$45-S$5)*($A10-$A$5)/($A$45-$A$5),0) -> 33079 | T10: =UVU!C29-SUM(U10:X10) -> 32457 | U10: 680 | V10: =ROUND(V$6+(V$45-V$6)*($A10-$A$6)/($A$45-$A$6),0) -> 428
A11: 2016 | B11: =LDSBC!B7 -> 2631.5789 | C11: =Westminstor!B30 -> 3245 | D11: =U!$F48 * D$2 -> 27583.35 | E11: =U!$F48 * E$2 -> 4867.65 | F11: =F10+0.45*(WSU!F129-WSU!F128) -> 21183 | G11: =G10+0.45*(WSU!F129-WSU!F128) -> 5167 | H11: =H10+0.1*(WSU!F129-WSU!F128) -> 886 | I11: =ROUND(slcc!$C30*M$48,0) -> 15874 | J11: =ROUND(slcc!$C30*N$48,0) -> 5366 | K11: =ROUND(slcc!$C30*O$48,0) -> 6009 | L11: =ROUND(slcc!$C30*P$48,0) -> 225 | M11: =ROUND(slcc!$C30*Q$48,0) -> 2281 | N11: =ROUND(slcc!$C30*R$48,0) -> 996 | O11: =ROUND(slcc!$C30*S$48,0) -> 900 | P11: =P10+20 -> 320 | Q11: =ROUND(slcc!$C30*U$48,0) -> 353 | S11: =ROUND(S$5+(S$45-S$5)*($A11-$A$5)/($A$45-$A$5),0) -> 33105 | T11: =UVU!C30-SUM(U11:X11) -> 33992 | U11: =ROUND(U$10+(U$45-U$10)*($A11-$A$10)/($A$45-$A$10),0) -> 699 | V11: =ROUND(V$6+(V$45-V$6)*($A11-$A$6)/($A$45-$A$6),0) -> 435
A12: 2017 | B12: =LDSBC!B8 -> 2739.4737 | C12: =Westminstor!B31 -> 3252.5 | D12: =U!$F49 * D$2 -> 28180.05 | E12: =U!$F49 * E$2 -> 4972.95 | F12: =F11+0.45*(WSU!F130-WSU!F129) -> 21697.35 | G12: =G11+0.45*(WSU!F130-WSU!F129) -> 5681.35 | H12: =H11+0.1*(WSU!F130-WSU!F129) -> 1000.3 | I12: =ROUND(slcc!$C31*M$48,0) -> 15945 | J12: =ROUND(slcc!$C31*N$48,0) -> 5390 | K12: =ROUND(slcc!$C31*O$48,0) -> 6036 | L12: =ROUND(slcc!$C31*P$48,0) -> 226 | M12: =ROUND(slcc!$C31*Q$48,0) -> 2292 | N12: =ROUND(slcc!$C31*R$48,0) -> 1001 | O12: =ROUND(slcc!$C31*S$48,0) -> 904 | P12: =P11+20 -> 340 | Q12: =ROUND(slcc!$C31*U$48,0) -> 355 | S12: =ROUND(S$5+(S$45-S$5)*($A12-$A$5)/($A$45-$A$5),0) -> 33131 | T12: =UVU!C31-SUM(U12:X12) -> 36625 | U12: =ROUND(U$10+(U$45-U$10)*($A12-$A$10)/($A$45-$A$10),0) -> 718 | V12: =ROUND(V$6+(V$45-V$6)*($A12-$A$6)/($A$45-$A$6),0) -> 442
A13: 2018 | B13: =LDSBC!B9 -> 2847.3684 | C13: =Westminstor!B32 -> 3260 | D13: =U!$F50 * D$2 -> 29109.95 | E13: =U!$F50 * E$2 -> 5137.05 | F13: =F12+0.45*(WSU!F131-WSU!F130) -> 22755.251 | G13: =G12+0.45*(WSU!F131-WSU!F130) -> 6739.251 | H13: =H12+0.1*(WSU!F131-WSU!F130) -> 1235.3891 | I13: =ROUND(slcc!$C32*M$48,0) -> 16295 | J13: =ROUND(slcc!$C32*N$48,0) -> 5508 | K13: =ROUND(slcc!$C32*O$48,0) -> 6168 | L13: =ROUND(slcc!$C32*P$48,0) -> 231 | M13: =ROUND(slcc!$C32*Q$48,0) -> 2342 | N13: =ROUND(slcc!$C32*R$48,0) -> 1023 | O13: =ROUND(slcc!$C32*S$48,0) -> 924 | P13: =P12+20 -> 360 | Q13: =ROUND(slcc!$C32*U$48,0) -> 363 | S13: =ROUND(S$5+(S$45-S$5)*($A13-$A$5)/($A$45-$A$5),0) -> 33158 | T13: =UVU!C32-SUM(U13:X13) -> 36557.193 | U13: =ROUND(U$10+(U$45-U$10)*($A13-$A$10)/($A$45-$A$10),0) -> 737 | V13: =ROUND(V$6+(V$45-V$6)*($A13-$A$6)/($A$45-$A$6),0) -> 448
A14: 2019 | B14: =LDSBC!B10 -> 2955.2632 | C14: =Westminstor!B33 -> 3267.5 | D14: =U!$F51 * D$2 -> 29959.1 | E14: =U!$F51 * E$2 -> 5286.9 | F14: =F13+0.45*(WSU!F132-WSU!F131) -> 23382.042 | G14: =G13+0.45*(WSU!F132-WSU!F131) -> 7366.0424 | H14: =H13+0.1*(WSU!F132-WSU!F131) -> 1374.6761 | I14: =ROUND(slcc!$C33*M$48,0) -> 16627 | J14: =ROUND(slcc!$C33*N$48,0) -> 5621 | K14: =ROUND(slcc!$C33*O$48,0) -> 6294 | L14: =ROUND(slcc!$C33*P$48,0) -> 236 | M14: =ROUND(slcc!$C33*Q$48,0) -> 2390 | N14: =ROUND(slcc!$C33*R$48,0) -> 1043 | O14: =ROUND(slcc!$C33*S$48,0) -> 942 | P14: =P13+20 -> 380 | Q14: =ROUND(slcc!$C33*U$48,0) -> 370 | S14: =ROUND(S$5+(S$45-S$5)*($A14-$A$5)/($A$45-$A$5),0) -> 33184 | T14: =UVU!C33-SUM(U14:X14) -> 37930.643 | U14: =ROUND(U$10+(U$45-U$10)*($A14-$A$10)/($A$45-$A$10),0) -> 755 | V14: =ROUND(V$6+(V$45-V$6)*($A14-$A$6)/($A$45-$A$6),0) -> 455
A15: 2020 | B15: =LDSBC!B11 -> 3063.1579 | C15: =Westminstor!B34 -> 3275 | D15: =U!$F52 * D$2 -> 30666.3 | E15: =U!$F52 * E$2 -> 5411.7 | F15: =F14+0.45*(WSU!F133-WSU!F132) -> 24004.267 | G15: =G14+0.45*(WSU!F133-WSU!F132) -> 7988.2666 | H15: =H14+0.1*(WSU!F133-WSU!F132) -> 1512.9481 | I15: =ROUND(slcc!$C34*M$48,0) -> 16968 | J15: =ROUND(slcc!$C34*N$48,0) -> 5736 | K15: =ROUND(slcc!$C34*O$48,0) -> 6423 | L15: =ROUND(slcc!$C34*P$48,0) -> 240 | M15: =ROUND(slcc!$C34*Q$48,0) -> 2439 | N15: =ROUND(slcc!$C34*R$48,0) -> 1065 | O15: =ROUND(slcc!$C34*S$48,0) -> 962 | P15: =P14+20 -> 400 | Q15: =ROUND(slcc!$C34*U$48,0) -> 378 | S15: =ROUND(S$5+(S$45-S$5)*($A15-$A$5)/($A$45-$A$5),0) -> 33210 | T15: =UVU!C34-SUM(U15:X15) -> 39358.186 | U15: =ROUND(U$10+(U$45-U$10)*($A15-$A$10)/($A$45-$A$10),0) -> 774 | V15: =ROUND(V$6+(V$45-V$6)*($A15-$A$6)/($A$45-$A$6),0) -> 462
A16: 2021 | B16: =LDSBC!B12 -> 3171.0526 | C16: =Westminstor!B35 -> 3282.5 | D16: =U!$F53 * D$2 -> 30990.15 | E16: =U!$F53 * E$2 -> 5468.85 | F16: =F15+0.45*(WSU!F134-WSU!F133) -> 24610.161 | G16: =G15+0.45*(WSU!F134-WSU!F133) -> 8594.1612 | H16: =H15+0.1*(WSU!F134-WSU!F133) -> 1647.5914 | I16: =ROUND(slcc!$C35*M$48,0) -> 17316 | J16: =ROUND(slcc!$C35*N$48,0) -> 5854 | K16: =ROUND(slcc!$C35*O$48,0) -> 6555 | L16: =ROUND(slcc!$C35*P$48,0) -> 245 | M16: =ROUND(slcc!$C35*Q$48,0) -> 2489 | N16: =ROUND(slcc!$C35*R$48,0) -> 1087 | O16: =ROUND(slcc!$C35*S$48,0) -> 981 | P16: =P15+20 -> 420 | Q16: =ROUND(slcc!$C35*U$48,0) -> 386 | S16: =ROUND(S$5+(S$45-S$5)*($A16-$A$5)/($A$45-$A$5),0) -> 33237 | T16: =UVU!C35-SUM(U16:X16) -> 40617.821 | U16: =ROUND(U$10+(U$45-U$10)*($A16-$A$10)/($A$45-$A$10),0) -> 793 | V16: =ROUND(V$6+(V$45-V$6)*($A16-$A$6)/($A$45-$A$6),0) -> 469
A17: 2022 | B17: =LDSBC!B13 -> 3278.9474 | C17: =Westminstor!B36 -> 3290 | D17: =U!$F54 * D$2 -> 31236.65 | E17: =U!$F54 * E$2 -> 5512.35 | F17: =F16+0.45*(WSU!F135-WSU!F134) -> 25193.797 | G17: =G16+0.45*(WSU!F135-WSU!F134) -> 9177.797 | H17: =H16+0.1*(WSU!F135-WSU!F134) -> 1777.2882 | I17: =ROUND(slcc!$C36*M$48,0) -> 17665 | J17: =ROUND(slcc!$C36*N$48,0) -> 5972 | K17: =ROUND(slcc!$C36*O$48,0) -> 6687 | L17: =ROUND(slcc!$C36*P$48,0) -> 250 | M17: =ROUND(slcc!$C36*Q$48,0) -> 2539 | N17: =ROUND(slcc!$C36*R$48,0) -> 1109 | O17: =ROUND(slcc!$C36*S$48,0) -> 1001 | P17: =P16+20 -> 440 | Q17: =ROUND(slcc!$C36*U$48,0) -> 393 | S17: =ROUND(S$5+(S$45-S$5)*($A17-$A$5)/($A$45-$A$5),0) -> 33263 | T17: =UVU!C36-SUM(U17:X17) -> 42059.167 | U17: =ROUND(U$10+(U$45-U$10)*($A17-$A$10)/($A$45-$A$10),0) -> 812 | V17: =ROUND(V$6+(V$45-V$6)*($A17-$A$6)/($A$45-$A$6),0) -> 476
A18: 2023 | B18: =LDSBC!B14 -> 3386.8421 | C18: =Westminstor!B37 -> 3297.5 | D18: =U!$F55 * D$2 -> 31499.3 | E18: =U!$F55 * E$2 -> 5558.7 | F18: =F17+0.45*(WSU!F136-WSU!F135) -> 25753.623 | G18: =G17+0.45*(WSU!F136-WSU!F135) -> 9737.6228 | H18: =H17+0.1*(WSU!F136-WSU!F135) -> 1901.6939 | I18: =ROUND(slcc!$C37*M$48,0) -> 18015 | J18: =ROUND(slcc!$C37*N$48,0) -> 6090 | K18: =ROUND(slcc!$C37*O$48,0) -> 6820 | L18: =ROUND(slcc!$C37*P$48,0) -> 255 | M18: =ROUND(slcc!$C37*Q$48,0) -> 2589 | N18: =ROUND(slcc!$C37*R$48,0) -> 1131 | O18: =ROUND(slcc!$C37*S$48,0) -> 1021 | P18: =P17+20 -> 460 | Q18: =ROUND(slcc!$C37*U$48,0) -> 401 | S18: =ROUND(S$5+(S$45-S$5)*($A18-$A$5)/($A$45-$A$5),0) -> 33289 | T18: =UVU!C37-SUM(U18:X18) -> 43355.776 | U18: =ROUND(U$10+(U$45-U$10)*($A18-$A$10)/($A$45-$A$10),0) -> 831 | V18: =ROUND(V$6+(V$45-V$6)*($A18-$A$6)/($A$45-$A$6),0) -> 483 | W18: 200
A19: 2024 | B19: =LDSBC!B15 -> 3494.7368 | C19: =Westminstor!B38 -> 3305 | D19: =U!$F56 * D$2 -> 31885.2 | E19: =U!$F56 * E$2 -> 5626.8 | F19: =F18+0.45*(WSU!F137-WSU!F136) -> 26291.059 | G19: =G18+0.45*(WSU!F137-WSU!F136) -> 10275.059 | H19: =H18+0.1*(WSU!F137-WSU!F136) -> 2021.1242 | I19: =ROUND(slcc!$C38*M$48,0) -> 18361 | J19: =ROUND(slcc!$C38*N$48,0) -> 6207 | K19: =ROUND(slcc!$C38*O$48,0) -> 6950 | L19: =ROUND(slcc!$C38*P$48,0) -> 260 | M19: =ROUND(slcc!$C38*Q$48,0) -> 2639 | N19: =ROUND(slcc!$C38*R$48,0) -> 1152 | O19: =ROUND(slcc!$C38*S$48,0) -> 1041 | P19: =P18+20 -> 480 | Q19: =ROUND(slcc!$C38*U$48,0) -> 409 | R19: 400 | S19: =ROUND(S$5+(S$45-S$5)*($A19-$A$5)/($A$45-$A$5),0) -> 33316 | T19: =UVU!C38-SUM(U19:X19) -> 44856.208 | U19: =ROUND(U$10+(U$45-U$10)*($A19-$A$10)/($A$45-$A$10),0) -> 850 | V19: =ROUND(V$6+(V$45-V$6)*($A19-$A$6)/($A$45-$A$6),0) -> 490 | W19: =W18+(W$45-$W$18)/($A$45-$A$18) -> 254.62963
A20: 2025 | B20: =LDSBC!B16 -> 3602.6316 | C20: =Westminstor!B39 -> 3312.5 | D20: =U!$F57 * D$2 -> 32363.75 | E20: =U!$F57 * E$2 -> 5711.25 | F20: =F19+0.45*(WSU!F138-WSU!F137) -> 26809.208 | G20: =G19+0.45*(WSU!F138-WSU!F137) -> 10793.208 | H20: =H19+0.1*(WSU!F138-WSU!F137) -> 2136.2684 | I20: =ROUND(slcc!$C39*M$48,0) -> 18707 | J20: =ROUND(slcc!$C39*N$48,0) -> 6324 | K20: =ROUND(slcc!$C39*O$48,0) -> 7082 | L20: =ROUND(slcc!$C39*P$48,0) -> 265 | M20: =ROUND(slcc!$C39*Q$48,0) -> 2689 | N20: =ROUND(slcc!$C39*R$48,0) -> 1174 | O20: =ROUND(slcc!$C39*S$48,0) -> 1060 | P20: =P19+20 -> 500 | Q20: =ROUND(slcc!$C39*U$48,0) -> 417 | R20: =R19+224 -> 624 | S20: =ROUND(S$5+(S$45-S$5)*($A20-$A$5)/($A$45-$A$5),0) -> 33342 | T20: =UVU!C39-SUM(U20:X20) -> 46416.373 | U20: =ROUND(U$10+(U$45-U$10)*($A20-$A$10)/($A$45-$A$10),0) -> 869 | V20: =ROUND(V$6+(V$45-V$6)*($A20-$A$6)/($A$45-$A$6),0) -> 497 | W20: =W19+(W$45-$W$18)/($A$45-$A$18) -> 309.25926
A21: 2026 | B21: =LDSBC!B17 -> 3710.5263 | C21: =Westminstor!B40 -> 3320 | D21: =U!$F58 * D$2 -> 32839.75 | E21: =U!$F58 * E$2 -> 5795.25 | F21: =F20+0.45*(WSU!F139-WSU!F138) -> 27265.627 | G21: =G20+0.45*(WSU!F139-WSU!F138) -> 11249.627 | H21: =H20+0.1*(WSU!F139-WSU!F138) -> 2237.6949 | I21: =ROUND(slcc!$C40*M$48,0) -> 19050 | J21: =ROUND(slcc!$C40*N$48,0) -> 6440 | K21: =ROUND(slcc!$C40*O$48,0) -> 7211 | L21: =ROUND(slcc!$C40*P$48,0) -> 270 | M21: =ROUND(slcc!$C40*Q$48,0) -> 2738 | N21: =ROUND(slcc!$C40*R$48,0) -> 1195 | O21: =ROUND(slcc!$C40*S$48,0) -> 1080 | P21: =P20+20 -> 520 | Q21: =ROUND(slcc!$C40*U$48,0) -> 424 | R21: =R20+224 -> 848 | S21: =ROUND(S$5+(S$45-S$5)*($A21-$A$5)/($A$45-$A$5),0) -> 33368 | T21: =UVU!C40-SUM(U21:X21) -> 48040.111 | U21: =ROUND(U$10+(U$45-U$10)*($A21-$A$10)/($A$45-$A$10),0) -> 887 | V21: =ROUND(V$6+(V$45-V$6)*($A21-$A$6)/($A$45-$A$6),0) -> 504 | W21: =W20+(W$45-$W$18)/($A$45-$A$18) -> 363.88889
A22: 2027 | B22: =LDSBC!B18 -> 3818.4211 | C22: =Westminstor!B41 -> 3327.5 | D22: =U!$F59 * D$2 -> 33274.1 | E22: =U!$F59 * E$2 -> 5871.9 | F22: =ROUND(F$21+(F$45-F$21)*($A22-$A$21)/($A$45-$A$21),0) -> 27308 | G22: =ROUND(G$21+(G$45-G$21)*($A22-$A$21)/($A$45-$A$21),0) -> 11292 | H22: =ROUND(H$21+(H$45-H$21)*($A22-$A$21)/($A$45-$A$21),0) -> 2247 | I22: =ROUND(slcc!$C41*M$48,0) -> 19603 | J22: =ROUND(slcc!$C41*N$48,0) -> 6627 | K22: =ROUND(slcc!$C41*O$48,0) -> 7420 | L22: =ROUND(slcc!$C41*P$48,0) -> 278 | M22: =ROUND(slcc!$C41*Q$48,0) -> 2817 | N22: =ROUND(slcc!$C41*R$48,0) -> 1230 | O22: =ROUND(slcc!$C41*S$48,0) -> 1111 | P22: =P21+20 -> 540 | Q22: =ROUND(slcc!$C41*U$48,0) -> 436 | R22: =R21+224 -> 1072 | S22: =ROUND(S$5+(S$45-S$5)*($A22-$A$5)/($A$45-$A$5),0) -> 33395 | T22: =UVU!C41-SUM(U22:X22) -> 48648.44 | U22: =ROUND(U$10+(U$45-U$10)*($A22-$A$10)/($A$45-$A$10),0) -> 906 | V22: =ROUND(V$6+(V$45-V$6)*($A22-$A$6)/($A$45-$A$6),0) -> 511 | W22: =W21+(W$45-$W$18)/($A$45-$A$18) -> 418.51852
A23: 2028 | B23: =LDSBC!B19 -> 3926.3158 | C23: =Westminstor!B42 -> 3335 | D23: =U!$F60 * D$2 -> 33666.8 | E23: =U!$F60 * E$2 -> 5941.2 | F23: =ROUND(F$21+(F$45-F$21)*($A23-$A$21)/($A$45-$A$21),0) -> 27350 | G23: =ROUND(G$21+(G$45-G$21)*($A23-$A$21)/($A$45-$A$21),0) -> 11334 | H23: =ROUND(H$21+(H$45-H$21)*($A23-$A$21)/($A$45-$A$21),0) -> 2256 | I23: =ROUND(slcc!$C42*M$48,0) -> 20155 | J23: =ROUND(slcc!$C42*N$48,0) -> 6814 | K23: =ROUND(slcc!$C42*O$48,0) -> 7630 | L23: =ROUND(slcc!$C42*P$48,0) -> 286 | M23: =ROUND(slcc!$C42*Q$48,0) -> 2897 | N23: =ROUND(slcc!$C42*R$48,0) -> 1265 | O23: =ROUND(slcc!$C42*S$48,0) -> 1142 | P23: =P22+20 -> 560 | Q23: =ROUND(slcc!$C42*U$48,0) -> 449 | R23: =R22+224 -> 1296 | S23: =ROUND(S$5+(S$45-S$5)*($A23-$A$5)/($A$45-$A$5),0) -> 33421 | T23: =UVU!C42-SUM(U23:X23) -> 49256.769 | U23: =ROUND(U$10+(U$45-U$10)*($A23-$A$10)/($A$45-$A$10),0) -> 925 | V23: =ROUND(V$6+(V$45-V$6)*($A23-$A$6)/($A$45-$A$6),0) -> 518 | W23: =W22+(W$45-$W$18)/($A$45-$A$18) -> 473.14815
A24: 2029 | B24: =LDSBC!B20 -> 4034.2105 | C24: =Westminstor!B43 -> 3342.5 | D24: =U!$F61 * D$2 -> 34017.85 | E24: =U!$F61 * E$2 -> 6003.15 | F24: =ROUND(F$21+(F$45-F$21)*($A24-$A$21)/($A$45-$A$21),0) -> 27392 | G24: =ROUND(G$21+(G$45-G$21)*($A24-$A$21)/($A$45-$A$21),0) -> 11376 | H24: =ROUND(H$21+(H$45-H$21)*($A24-$A$21)/($A$45-$A$21),0) -> 2266 | I24: =ROUND(slcc!$C43*M$48,0) -> 20707 | J24: =ROUND(slcc!$C43*N$48,0) -> 7000 | K24: =ROUND(slcc!$C43*O$48,0) -> 7839 | L24: =ROUND(slcc!$C43*P$48,0) -> 293 | M24: =ROUND(slcc!$C43*Q$48,0) -> 2976 | N24: =ROUND(slcc!$C43*R$48,0) -> 1299 | O24: =ROUND(slcc!$C43*S$48,0) -> 1174 | P24: =P23+20 -> 580 | Q24: =ROUND(slcc!$C43*U$48,0) -> 461 | R24: =R23+224 -> 1520 | S24: =ROUND(S$5+(S$45-S$5)*($A24-$A$5)/($A$45-$A$5),0) -> 33447 | T24: =UVU!C43-SUM(U24:X24) -> 49865.097 | U24: =ROUND(U$10+(U$45-U$10)*($A24-$A$10)/($A$45-$A$10),0) -> 944 | V24: =ROUND(V$6+(V$45-V$6)*($A24-$A$6)/($A$45-$A$6),0) -> 525 | W24: =W23+(W$45-$W$18)/($A$45-$A$18) -> 527.77778
A25: 2030 | B25: =LDSBC!B21 -> 4142.1053 | C25: =Westminstor!B44 -> 3350 | D25: =U!$F62 * D$2 -> 34327.25 | E25: =U!$F62 * E$2 -> 6057.75 | F25: =ROUND(F$21+(F$45-F$21)*($A25-$A$21)/($A$45-$A$21),0) -> 27434 | G25: =ROUND(G$21+(G$45-G$21)*($A25-$A$21)/($A$45-$A$21),0) -> 11418 | H25: =ROUND(H$21+(H$45-H$21)*($A25-$A$21)/($A$45-$A$21),0) -> 2275 | I25: =ROUND(slcc!$C44*M$48,0) -> 21260 | J25: =ROUND(slcc!$C44*N$48,0) -> 7187 | K25: =ROUND(slcc!$C44*O$48,0) -> 8048 | L25: =ROUND(slcc!$C44*P$48,0) -> 301 | M25: =ROUND(slcc!$C44*Q$48,0) -> 3056 | N25: =ROUND(slcc!$C44*R$48,0) -> 1334 | O25: =ROUND(slcc!$C44*S$48,0) -> 1205 | P25: =P24+20 -> 600 | Q25: =ROUND(slcc!$C44*U$48,0) -> 473 | R25: =R24+224 -> 1744 | S25: =ROUND(S$5+(S$45-S$5)*($A25-$A$5)/($A$45-$A$5),0) -> 33474 | T25: =UVU!C44-SUM(U25:X25) -> 50473.426 | U25: =ROUND(U$10+(U$45-U$10)*($A25-$A$10)/($A$45-$A$10),0) -> 963 | V25: =ROUND(V$6+(V$45-V$6)*($A25-$A$6)/($A$45-$A$6),0) -> 532 | W25: =W24+(W$45-$W$18)/($A$45-$A$18) -> 582.40741
A26: 2031 | B26: =LDSBC!B22 -> 4250 | C26: =Westminstor!B45 -> 3357.5 | D26: =U!$F63 * D$2 -> 34595 | E26: =U!$F63 * E$2 -> 6105 | F26: =ROUND(F$21+(F$45-F$21)*($A26-$A$21)/($A$45-$A$21),0) -> 27476 | G26: =ROUND(G$21+(G$45-G$21)*($A26-$A$21)/($A$45-$A$21),0) -> 11460 | H26: =ROUND(H$21+(H$45-H$21)*($A26-$A$21)/($A$45-$A$21),0) -> 2285 | I26: =ROUND(slcc!$C45*M$48,0) -> 21812 | J26: =ROUND(slcc!$C45*N$48,0) -> 7374 | K26: =ROUND(slcc!$C45*O$48,0) -> 8257 | L26: =ROUND(slcc!$C45*P$48,0) -> 309 | M26: =ROUND(slcc!$C45*Q$48,0) -> 3135 | N26: =ROUND(slcc!$C45*R$48,0) -> 1369 | O26: =ROUND(slcc!$C45*S$48,0) -> 1236 | P26: =P25+20 -> 620 | Q26: =ROUND(slcc!$C45*U$48,0) -> 486 | R26: =R25+224 -> 1968 | S26: =ROUND(S$5+(S$45-S$5)*($A26-$A$5)/($A$45-$A$5),0) -> 33500 | T26: =UVU!C45-SUM(U26:X26) -> 51082.755 | U26: =ROUND(U$10+(U$45-U$10)*($A26-$A$10)/($A$45-$A$10),0) -> 982 | V26: =ROUND(V$6+(V$45-V$6)*($A26-$A$6)/($A$45-$A$6),0) -> 538 | W26: =W25+(W$45-$W$18)/($A$45-$A$18) -> 637.03704
A27: 2032 | B27: =LDSBC!B23 -> 4357.8947 | C27: =Westminstor!B46 -> 3365 | D27: =U!$F64 * D$2 -> 34821.1 | E27: =U!$F64 * E$2 -> 6144.9 | F27: =ROUND(F$21+(F$45-F$21)*($A27-$A$21)/($A$45-$A$21),0) -> 27518 | G27: =ROUND(G$21+(G$45-G$21)*($A27-$A$21)/($A$45-$A$21),0) -> 11502 | H27: =ROUND(H$21+(H$45-H$21)*($A27-$A$21)/($A$45-$A$21),0) -> 2294 | I27: =ROUND(slcc!$C46*M$48,0) -> 22365 | J27: =ROUND(slcc!$C46*N$48,0) -> 7561 | K27: =ROUND(slcc!$C46*O$48,0) -> 8466 | L27: =ROUND(slcc!$C46*P$48,0) -> 317 | M27: =ROUND(slcc!$C46*Q$48,0) -> 3214 | N27: =ROUND(slcc!$C46*R$48,0) -> 1403 | O27: =ROUND(slcc!$C46*S$48,0) -> 1268 | P27: =P26+20 -> 640 | Q27: =ROUND(slcc!$C46*U$48,0) -> 498 | R27: =R26+224 -> 2192 | S27: =ROUND(S$5+(S$45-S$5)*($A27-$A$5)/($A$45-$A$5),0) -> 33526 | T27: =UVU!C46-SUM(U27:X27) -> 51691.083 | U27: =ROUND(U$10+(U$45-U$10)*($A27-$A$10)/($A$45-$A$10),0) -> 1001 | V27: =ROUND(V$6+(V$45-V$6)*($A27-$A$6)/($A$45-$A$6),0) -> 545 | W27: =W26+(W$45-$W$18)/($A$45-$A$18) -> 691.66667
A28: 2033 | B28: =LDSBC!B24 -> 4465.7895 | C28: =Westminstor!B47 -> 3372.5 | D28: =U!$F65 * D$2 -> 35005.55 | E28: =U!$F65 * E$2 -> 6177.45 | F28: =ROUND(F$21+(F$45-F$21)*($A28-$A$21)/($A$45-$A$21),0) -> 27561 | G28: =ROUND(G$21+(G$45-G$21)*($A28-$A$21)/($A$45-$A$21),0) -> 11545 | H28: =ROUND(H$21+(H$45-H$21)*($A28-$A$21)/($A$45-$A$21),0) -> 2303 | I28: =ROUND(slcc!$C47*M$48,0) -> 22917 | J28: =ROUND(slcc!$C47*N$48,0) -> 7747 | K28: =ROUND(slcc!$C47*O$48,0) -> 8675 | L28: =ROUND(slcc!$C47*P$48,0) -> 325 | M28: =ROUND(slcc!$C47*Q$48,0) -> 3294 | N28: =ROUND(slcc!$C47*R$48,0) -> 1438 | O28: =ROUND(slcc!$C47*S$48,0) -> 1299 | P28: =P27+20 -> 660 | Q28: =ROUND(slcc!$C47*U$48,0) -> 510 | R28: =R27+224 -> 2416 | S28: =ROUND(S$5+(S$45-S$5)*($A28-$A$5)/($A$45-$A$5),0) -> 33552 | T28: =UVU!C47-SUM(U28:X28) -> 52000.412 | U28: =ROUND(U$10+(U$45-U$10)*($A28-$A$10)/($A$45-$A$10),0) -> 1019 | V28: =ROUND(V$6+(V$45-V$6)*($A28-$A$6)/($A$45-$A$6),0) -> 552 | W28: =W27+(W$45-$W$18)/($A$45-$A$18) -> 746.2963 | X28: 300
A29: 2034 | B29: =LDSBC!B25 -> 4573.6842 | C29: =Westminstor!B48 -> 3380 | D29: =U!$F66 * D$2 -> 35148.35 | E29: =U!$F66 * E$2 -> 6202.65 | F29: =ROUND(F$21+(F$45-F$21)*($A29-$A$21)/($A$45-$A$21),0) -> 27603 | G29: =ROUND(G$21+(G$45-G$21)*($A29-$A$21)/($A$45-$A$21),0) -> 11587 | H29: =ROUND(H$21+(H$45-H$21)*($A29-$A$21)/($A$45-$A$21),0) -> 2313 | I29: =ROUND(slcc!$C48*M$48,0) -> 23469 | J29: =ROUND(slcc!$C48*N$48,0) -> 7934 | K29: =ROUND(slcc!$C48*O$48,0) -> 8884 | L29: =ROUND(slcc!$C48*P$48,0) -> 333 | M29: =ROUND(slcc!$C48*Q$48,0) -> 3373 | N29: =ROUND(slcc!$C48*R$48,0) -> 1473 | O29: =ROUND(slcc!$C48*S$48,0) -> 1330 | P29: =P28+20 -> 680 | Q29: =ROUND(slcc!$C48*U$48,0) -> 523 | R29: =R28+224 -> 2640 | S29: =ROUND(S$5+(S$45-S$5)*($A29-$A$5)/($A$45-$A$5),0) -> 33579 | T29: =UVU!C48-SUM(U29:X29) -> 52527.858 | U29: =ROUND(U$10+(U$45-U$10)*($A29-$A$10)/($A$45-$A$10),0) -> 1038 | V29: =ROUND(V$6+(V$45-V$6)*($A29-$A$6)/($A$45-$A$6),0) -> 559 | W29: =W28+(W$45-$W$18)/($A$45-$A$18) -> 800.92593 | X29: =X28+(X$45-$X$28)/($A$45-$A$28) -> 380.88235
A30: 2035 | B30: =LDSBC!B26 -> 4681.5789 | C30: =Westminstor!B49 -> 3387.5 | D30: =U!$F67 * D$2 -> 35278.4 | E30: =U!$F67 * E$2 -> 6225.6 | F30: =ROUND(F$21+(F$45-F$21)*($A30-$A$21)/($A$45-$A$21),0) -> 27645 | G30: =ROUND(G$21+(G$45-G$21)*($A30-$A$21)/($A$45-$A$21),0) -> 11629 | H30: =ROUND(H$21+(H$45-H$21)*($A30-$A$21)/($A$45-$A$21),0) -> 2322 | I30: =ROUND(slcc!$C49*M$48,0) -> 24022 | J30: =ROUND(slcc!$C49*N$48,0) -> 8121 | K30: =ROUND(slcc!$C49*O$48,0) -> 9093 | L30: =ROUND(slcc!$C49*P$48,0) -> 340 | M30: =ROUND(slcc!$C49*Q$48,0) -> 3453 | N30: =ROUND(slcc!$C49*R$48,0) -> 1507 | O30: =ROUND(slcc!$C49*S$48,0) -> 1362 | P30: =P29+20 -> 700 | Q30: =ROUND(slcc!$C49*U$48,0) -> 535 | R30: =R29+224 -> 2864 | S30: =ROUND(S$5+(S$45-S$5)*($A30-$A$5)/($A$45-$A$5),0) -> 33605 | T30: =UVU!C49-SUM(U30:X30) -> 53055.305 | U30: =ROUND(U$10+(U$45-U$10)*($A30-$A$10)/($A$45-$A$10),0) -> 1057 | V30: =ROUND(V$6+(V$45-V$6)*($A30-$A$6)/($A$45-$A$6),0) -> 566 | W30: =W29+(W$45-$W$18)/($A$45-$A$18) -> 855.55556 | X30: =X29+(X$45-$X$28)/($A$45-$A$28) -> 461.76471
A31: 2036 | B31: =LDSBC!B27 -> 4789.4737 | C31: =Westminstor!B50 -> 3395 | D31: =U!$F68 * D$2 -> 35395.7 | E31: =U!$F68 * E$2 -> 6246.3 | F31: =ROUND(F$21+(F$45-F$21)*($A31-$A$21)/($A$45-$A$21),0) -> 27687 | G31: =ROUND(G$21+(G$45-G$21)*($A31-$A$21)/($A$45-$A$21),0) -> 11671 | H31: =ROUND(H$21+(H$45-H$21)*($A31-$A$21)/($A$45-$A$21),0) -> 2331 | I31: =ROUND(slcc!$C50*M$48,0) -> 24574 | J31: =ROUND(slcc!$C50*N$48,0) -> 8307 | K31: =ROUND(slcc!$C50*O$48,0) -> 9302 | L31: =ROUND(slcc!$C50*P$48,0) -> 348 | M31: =ROUND(slcc!$C50*Q$48,0) -> 3532 | N31: =ROUND(slcc!$C50*R$48,0) -> 1542 | O31: =ROUND(slcc!$C50*S$48,0) -> 1393 | P31: =P30+20 -> 720 | Q31: =ROUND(slcc!$C50*U$48,0) -> 547 | R31: =R30+224 -> 3088 | S31: =ROUND(S$5+(S$45-S$5)*($A31-$A$5)/($A$45-$A$5),0) -> 33631 | T31: =UVU!C50-SUM(U31:X31) -> 53582.751 | U31: =ROUND(U$10+(U$45-U$10)*($A31-$A$10)/($A$45-$A$10),0) -> 1076 | V31: =ROUND(V$6+(V$45-V$6)*($A31-$A$6)/($A$45-$A$6),0) -> 573 | W31: =W30+(W$45-$W$18)/($A$45-$A$18) -> 910.18519 | X31: =X30+(X$45-$X$28)/($A$45-$A$28) -> 542.64706
A32: 2037 | B32: =LDSBC!B28 -> 4897.3684 | C32: =Westminstor!B51 -> 3402.5 | D32: =U!$F69 * D$2 -> 35500.25 | E32: =U!$F69 * E$2 -> 6264.75 | F32: =ROUND(F$21+(F$45-F$21)*($A32-$A$21)/($A$45-$A$21),0) -> 27729 | G32: =ROUND(G$21+(G$45-G$21)*($A32-$A$21)/($A$45-$A$21),0) -> 11713 | H32: =ROUND(H$21+(H$45-H$21)*($A32-$A$21)/($A$45-$A$21),0) -> 2341 | I32: =ROUND(slcc!$C51*M$48,0) -> 25127 | J32: =ROUND(slcc!$C51*N$48,0) -> 8494 | K32: =ROUND(slcc!$C51*O$48,0) -> 9512 | L32: =ROUND(slcc!$C51*P$48,0) -> 356 | M32: =ROUND(slcc!$C51*Q$48,0) -> 3611 | N32: =ROUND(slcc!$C51*R$48,0) -> 1577 | O32: =ROUND(slcc!$C51*S$48,0) -> 1424 | P32: =P31+20 -> 740 | Q32: =ROUND(slcc!$C51*U$48,0) -> 560 | R32: =R31+224 -> 3312 | S32: =ROUND(S$5+(S$45-S$5)*($A32-$A$5)/($A$45-$A$5),0) -> 33658 | T32: =UVU!C51-SUM(U32:X32) -> 54110.197 | U32: =ROUND(U$10+(U$45-U$10)*($A32-$A$10)/($A$45-$A$10),0) -> 1095 | V32: =ROUND(V$6+(V$45-V$6)*($A32-$A$6)/($A$45-$A$6),0) -> 580 | W32: =W31+(W$45-$W$18)/($A$45-$A$18) -> 964.81481 | X32: =X31+(X$45-$X$28)/($A$45-$A$28) -> 623.52941
A33: 2038 | B33: =LDSBC!B29 -> 5005.2632 | C33: =Westminstor!B52 -> 3410 | D33: =U!$F70 * D$2 -> 35592.05 | E33: =U!$F70 * E$2 -> 6280.95 | F33: =ROUND(F$21+(F$45-F$21)*($A33-$A$21)/($A$45-$A$21),0) -> 27771 | G33: =ROUND(G$21+(G$45-G$21)*($A33-$A$21)/($A$45-$A$21),0) -> 11755 | H33: =ROUND(H$21+(H$45-H$21)*($A33-$A$21)/($A$45-$A$21),0) -> 2350 | I33: =ROUND(slcc!$C52*M$48,0) -> 25679 | J33: =ROUND(slcc!$C52*N$48,0) -> 8681 | K33: =ROUND(slcc!$C52*O$48,0) -> 9721 | L33: =ROUND(slcc!$C52*P$48,0) -> 364 | M33: =ROUND(slcc!$C52*Q$48,0) -> 3691 | N33: =ROUND(slcc!$C52*R$48,0) -> 1611 | O33: =ROUND(slcc!$C52*S$48,0) -> 1455 | P33: =P32+20 -> 760 | Q33: =ROUND(slcc!$C52*U$48,0) -> 572 | R33: =R32+224 -> 3536 | S33: =ROUND(S$5+(S$45-S$5)*($A33-$A$5)/($A$45-$A$5),0) -> 33684 | T33: =UVU!C52-SUM(U33:X33) -> 54637.644 | U33: =ROUND(U$10+(U$45-U$10)*($A33-$A$10)/($A$45-$A$10),0) -> 1114 | V33: =ROUND(V$6+(V$45-V$6)*($A33-$A$6)/($A$45-$A$6),0) -> 587 | W33: =W32+(W$45-$W$18)/($A$45-$A$18) -> 1019.4444 | X33: =X32+(X$45-$X$28)/($A$45-$A$28) -> 704.41176
A34: 2039 | B34: =LDSBC!B30 -> 5113.1579 | C34: =Westminstor!B53 -> 3417.5 | D34: =U!$F71 * D$2 -> 35671.1 | E34: =U!$F71 * E$2 -> 6294.9 | F34: =ROUND(F$21+(F$45-F$21)*($A34-$A$21)/($A$45-$A$21),0) -> 27813 | G34: =ROUND(G$21+(G$45-G$21)*($A34-$A$21)/($A$45-$A$21),0) -> 11797 | H34: =ROUND(H$21+(H$45-H$21)*($A34-$A$21)/($A$45-$A$21),0) -> 2359 | I34: =ROUND(slcc!$C53*M$48,0) -> 26232 | J34: =ROUND(slcc!$C53*N$48,0) -> 8868 | K34: =ROUND(slcc!$C53*O$48,0) -> 9930 | L34: =ROUND(slcc!$C53*P$48,0) -> 372 | M34: =ROUND(slcc!$C53*Q$48,0) -> 3770 | N34: =ROUND(slcc!$C53*R$48,0) -> 1646 | O34: =ROUND(slcc!$C53*S$48,0) -> 1487 | P34: =P33+20 -> 780 | Q34: =ROUND(slcc!$C53*U$48,0) -> 584 | R34: =R33+224 -> 3760 | S34: =ROUND(S$5+(S$45-S$5)*($A34-$A$5)/($A$45-$A$5),0) -> 33710 | T34: =UVU!C53-SUM(U34:X34) -> 55165.09 | U34: =ROUND(U$10+(U$45-U$10)*($A34-$A$10)/($A$45-$A$10),0) -> 1133 | V34: =ROUND(V$6+(V$45-V$6)*($A34-$A$6)/($A$45-$A$6),0) -> 594 | W34: =W33+(W$45-$W$18)/($A$45-$A$18) -> 1074.0741 | X34: =X33+(X$45-$X$28)/($A$45-$A$28) -> 785.29412
A35: 2040 | B35: =LDSBC!B31 -> 5221.0526 | C35: =Westminstor!B54 -> 3425 | D35: =U!$F72 * D$2 -> 35737.4 | E35: =U!$F72 * E$2 -> 6306.6 | F35: =ROUND(F$21+(F$45-F$21)*($A35-$A$21)/($A$45-$A$21),0) -> 27855 | G35: =ROUND(G$21+(G$45-G$21)*($A35-$A$21)/($A$45-$A$21),0) -> 11839 | H35: =ROUND(H$21+(H$45-H$21)*($A35-$A$21)/($A$45-$A$21),0) -> 2369 | I35: =ROUND(slcc!$C54*M$48,0) -> 26784 | J35: =ROUND(slcc!$C54*N$48,0) -> 9054 | K35: =ROUND(slcc!$C54*O$48,0) -> 10139 | L35: =ROUND(slcc!$C54*P$48,0) -> 380 | M35: =ROUND(slcc!$C54*Q$48,0) -> 3850 | N35: =ROUND(slcc!$C54*R$48,0) -> 1681 | O35: =ROUND(slcc!$C54*S$48,0) -> 1518 | P35: =P34+20 -> 800 | Q35: =ROUND(slcc!$C54*U$48,0) -> 596 | R35: =R34+224 -> 3984 | S35: =ROUND(S$5+(S$45-S$5)*($A35-$A$5)/($A$45-$A$5),0) -> 33737 | T35: =UVU!C54-SUM(U35:X35) -> 55693.536 | U35: =ROUND(U$10+(U$45-U$10)*($A35-$A$10)/($A$45-$A$10),0) -> 1151 | V35: =ROUND(V$6+(V$45-V$6)*($A35-$A$6)/($A$45-$A$6),0) -> 601 | W35: =W34+(W$45-$W$18)/($A$45-$A$18) -> 1128.7037 | X35: =X34+(X$45-$X$28)/($A$45-$A$28) -> 866.17647
A36: 2041 | B36: =LDSBC!B32 -> 5328.9474 | C36: =Westminstor!B55 -> 3432.5 | D36: =U!$F73 * D$2 -> 35790.95 | E36: =U!$F73 * E$2 -> 6316.05 | F36: =ROUND(F$21+(F$45-F$21)*($A36-$A$21)/($A$45-$A$21),0) -> 27898 | G36: =ROUND(G$21+(G$45-G$21)*($A36-$A$21)/($A$45-$A$21),0) -> 11882 | H36: =ROUND(H$21+(H$45-H$21)*($A36-$A$21)/($A$45-$A$21),0) -> 2378 | I36: =ROUND(slcc!$C55*M$48,0) -> 27336 | J36: =ROUND(slcc!$C55*N$48,0) -> 9241 | K36: =ROUND(slcc!$C55*O$48,0) -> 10348 | L36: =ROUND(slcc!$C55*P$48,0) -> 387 | M36: =ROUND(slcc!$C55*Q$48,0) -> 3929 | N36: =ROUND(slcc!$C55*R$48,0) -> 1715 | O36: =ROUND(slcc!$C55*S$48,0) -> 1549 | P36: =P35+20 -> 820 | Q36: =ROUND(slcc!$C55*U$48,0) -> 609 | R36: =R35+224 -> 4208 | S36: =ROUND(S$5+(S$45-S$5)*($A36-$A$5)/($A$45-$A$5),0) -> 33763 | T36: =UVU!C55-SUM(U36:X36) -> 56220.983 | U36: =ROUND(U$10+(U$45-U$10)*($A36-$A$10)/($A$45-$A$10),0) -> 1170 | V36: =ROUND(V$6+(V$45-V$6)*($A36-$A$6)/($A$45-$A$6),0) -> 608 | W36: =W35+(W$45-$W$18)/($A$45-$A$18) -> 1183.3333 | X36: =X35+(X$45-$X$28)/($A$45-$A$28) -> 947.05882
A37: 2042 | B37: =LDSBC!B33 -> 5436.8421 | C37: =Westminstor!B56 -> 3440 | D37: =U!$F74 * D$2 -> 35831.75 | E37: =U!$F74 * E$2 -> 6323.25 | F37: =ROUND(F$21+(F$45-F$21)*($A37-$A$21)/($A$45-$A$21),0) -> 27940 | G37: =ROUND(G$21+(G$45-G$21)*($A37-$A$21)/($A$45-$A$21),0) -> 11924 | H37: =ROUND(H$21+(H$45-H$21)*($A37-$A$21)/($A$45-$A$21),0) -> 2387 | I37: =ROUND(slcc!$C56*M$48,0) -> 27889 | J37: =ROUND(slcc!$C56*N$48,0) -> 9428 | K37: =ROUND(slcc!$C56*O$48,0) -> 10557 | L37: =ROUND(slcc!$C56*P$48,0) -> 395 | M37: =ROUND(slcc!$C56*Q$48,0) -> 4008 | N37: =ROUND(slcc!$C56*R$48,0) -> 1750 | O37: =ROUND(slcc!$C56*S$48,0) -> 1581 | P37: =P36+20 -> 840 | Q37: =ROUND(slcc!$C56*U$48,0) -> 621 | R37: =R36+224 -> 4432 | S37: =ROUND(S$5+(S$45-S$5)*($A37-$A$5)/($A$45-$A$5),0) -> 33789 | T37: =UVU!C56-SUM(U37:X37) -> 56748.429 | U37: =ROUND(U$10+(U$45-U$10)*($A37-$A$10)/($A$45-$A$10),0) -> 1189 | V37: =ROUND(V$6+(V$45-V$6)*($A37-$A$6)/($A$45-$A$6),0) -> 615 | W37: =W36+(W$45-$W$18)/($A$45-$A$18) -> 1237.963 | X37: =X36+(X$45-$X$28)/($A$45-$A$28) -> 1027.9412
A38: 2043 | B38: =LDSBC!B34 -> 5544.7368 | C38: =Westminstor!B57 -> 3447.5 | D38: =U!$F75 * D$2 -> 35859.8 | E38: =U!$F75 * E$2 -> 6328.2 | F38: =ROUND(F$21+(F$45-F$21)*($A38-$A$21)/($A$45-$A$21),0) -> 27982 | G38: =ROUND(G$21+(G$45-G$21)*($A38-$A$21)/($A$45-$A$21),0) -> 11966 | H38: =ROUND(H$21+(H$45-H$21)*($A38-$A$21)/($A$45-$A$21),0) -> 2397 | I38: =ROUND(slcc!$C57*M$48,0) -> 28441 | J38: =ROUND(slcc!$C57*N$48,0) -> 9615 | K38: =ROUND(slcc!$C57*O$48,0) -> 10766 | L38: =ROUND(slcc!$C57*P$48,0) -> 403 | M38: =ROUND(slcc!$C57*Q$48,0) -> 4088 | N38: =ROUND(slcc!$C57*R$48,0) -> 1785 | O38: =ROUND(slcc!$C57*S$48,0) -> 1612 | P38: =P37+20 -> 860 | Q38: =ROUND(slcc!$C57*U$48,0) -> 633 | R38: =R37+224 -> 4656 | S38: =ROUND(S$5+(S$45-S$5)*($A38-$A$5)/($A$45-$A$5),0) -> 33816 | T38: =UVU!C57-SUM(U38:X38) -> 57275.876 | U38: =ROUND(U$10+(U$35-U$10)*($A38-$A$10)/($A$35-$A$10),0) -> 1208 | V38: =ROUND(V$6+(V$45-V$6)*($A38-$A$6)/($A$45-$A$6),0) -> 622 | W38: =W37+(W$45-$W$18)/($A$45-$A$18) -> 1292.5926 | X38: =X37+(X$45-$X$28)/($A$45-$A$28) -> 1108.8235
A39: 2044 | B39: =LDSBC!B35 -> 5652.6316 | C39: =Westminstor!B58 -> 3455 | D39: =U!$F76 * D$2 -> 35883.6 | E39: =U!$F76 * E$2 -> 6332.4 | F39: =ROUND(F$21+(F$45-F$21)*($A39-$A$21)/($A$45-$A$21),0) -> 28024 | G39: =ROUND(G$21+(G$45-G$21)*($A39-$A$21)/($A$45-$A$21),0) -> 12008 | H39: =ROUND(H$21+(H$45-H$21)*($A39-$A$21)/($A$45-$A$21),0) -> 2406 | I39: =ROUND(slcc!$C58*M$48,0) -> 28994 | J39: =ROUND(slcc!$C58*N$48,0) -> 9801 | K39: =ROUND(slcc!$C58*O$48,0) -> 10975 | L39: =ROUND(slcc!$C58*P$48,0) -> 411 | M39: =ROUND(slcc!$C58*Q$48,0) -> 4167 | N39: =ROUND(slcc!$C58*R$48,0) -> 1819 | O39: =ROUND(slcc!$C58*S$48,0) -> 1643 | P39: =P38+20 -> 880 | Q39: =ROUND(slcc!$C58*U$48,0) -> 646 | R39: =R38+224 -> 4880 | S39: =ROUND(S$5+(S$45-S$5)*($A39-$A$5)/($A$45-$A$5),0) -> 33842 | T39: =UVU!C58-SUM(U39:X39) -> 57805.322 | U39: =ROUND(U$10+(U$35-U$10)*($A39-$A$10)/($A$35-$A$10),0) -> 1226 | V39: =ROUND(V$6+(V$45-V$6)*($A39-$A$6)/($A$45-$A$6),0) -> 628 | W39: =W38+(W$45-$W$18)/($A$45-$A$18) -> 1347.2222 | X39: =X38+(X$45-$X$28)/($A$45-$A$28) -> 1189.7059
A40: 2045 | B40: =LDSBC!B36 -> 5760.5263 | C40: =Westminstor!B59 -> 3462.5 | D40: =U!$F77 * D$2 -> 35903.15 | E40: =U!$F77 * E$2 -> 6335.85 | F40: =ROUND(F$21+(F$45-F$21)*($A40-$A$21)/($A$45-$A$21),0) -> 28066 | G40: =ROUND(G$21+(G$45-G$21)*($A40-$A$21)/($A$45-$A$21),0) -> 12050 | H40: =ROUND(H$21+(H$45-H$21)*($A40-$A$21)/($A$45-$A$21),0) -> 2416 | I40: =ROUND(slcc!$C59*M$48,0) -> 29546 | J40: =ROUND(slcc!$C59*N$48,0) -> 9988 | K40: =ROUND(slcc!$C59*O$48,0) -> 11184 | L40: =ROUND(slcc!$C59*P$48,0) -> 419 | M40: =ROUND(slcc!$C59*Q$48,0) -> 4246 | N40: =ROUND(slcc!$C59*R$48,0) -> 1854 | O40: =ROUND(slcc!$C59*S$48,0) -> 1675 | P40: =P39+20 -> 900 | Q40: =ROUND(slcc!$C59*U$48,0) -> 658 | R40: =R39+224 -> 5104 | S40: =ROUND(S$5+(S$45-S$5)*($A40-$A$5)/($A$45-$A$5),0) -> 33868 | T40: =UVU!C59-SUM(U40:X40) -> 58332.768 | U40: =ROUND(U$10+(U$35-U$10)*($A40-$A$10)/($A$35-$A$10),0) -> 1245 | V40: =ROUND(V$6+(V$45-V$6)*($A40-$A$6)/($A$45-$A$6),0) -> 635 | W40: =W39+(W$45-$W$18)/($A$45-$A$18) -> 1401.8519 | X40: =X39+(X$45-$X$28)/($A$45-$A$28) -> 1270.5882
A41: 2046 | B41: =LDSBC!B37 -> 5868.4211 | C41: =Westminstor!B60 -> 3470 | D41: =U!$F78 * D$2 -> 35918.45 | E41: =U!$F78 * E$2 -> 6338.55 | F41: =ROUND(F$21+(F$45-F$21)*($A41-$A$21)/($A$45-$A$21),0) -> 28108 | G41: =ROUND(G$21+(G$45-G$21)*($A41-$A$21)/($A$45-$A$21),0) -> 12092 | H41: =ROUND(H$21+(H$45-H$21)*($A41-$A$21)/($A$45-$A$21),0) -> 2425 | I41: =ROUND(slcc!$C60*M$48,0) -> 30098 | J41: =ROUND(slcc!$C60*N$48,0) -> 10175 | K41: =ROUND(slcc!$C60*O$48,0) -> 11394 | L41: =ROUND(slcc!$C60*P$48,0) -> 426 | M41: =ROUND(slcc!$C60*Q$48,0) -> 4326 | N41: =ROUND(slcc!$C60*R$48,0) -> 1889 | O41: =ROUND(slcc!$C60*S$48,0) -> 1706 | P41: =P40+20 -> 920 | Q41: =ROUND(slcc!$C60*U$48,0) -> 670 | R41: =R40+224 -> 5328 | S41: =ROUND(S$5+(S$45-S$5)*($A41-$A$5)/($A$45-$A$5),0) -> 33895 | T41: =UVU!C60-SUM(U41:X41) -> 58860.215 | U41: =ROUND(U$10+(U$35-U$10)*($A41-$A$10)/($A$35-$A$10),0) -> 1264 | V41: =ROUND(V$6+(V$45-V$6)*($A41-$A$6)/($A$45-$A$6),0) -> 642 | W41: =W40+(W$45-$W$18)/($A$45-$A$18) -> 1456.4815 | X41: =X40+(X$45-$X$28)/($A$45-$A$28) -> 1351.4706
...

Sheet Calc%FTE
A1: Headcount | N1: Full-Time Equivalent
B2: Fall Semester | O2: Fall Semester
A3: Institution | B3: 2012 | C3: 2013 | D3: 2014 | E3: 2015 | F3: 2016 | G3: 2017 | H3: 2018 | I3: 2019 | J3: 2020 | K3: 2021 | L3: Average Annual Growth | N3: Institution | O3: 2012 | P3: 2013 | Q3: 2014 | R3: 2015 | S3: 2016 | T3: 2017 | U3: 2018 | V3: 2019 | W3: 2020 | X3: 2021 | Y3: Average Annual Growth
A4: University of Utah | B4: 33955 | C4: 34770 | D4: 35361 | E4: 35856 | F4: 36287 | G4: 36650 | H4: 36943 | I4: 37164 | J4: 37387 | K4: 37574 | N4: University of Utah | O4: 28067 | P4: 28741 | Q4: 29230 | R4: 29639 | S4: 29995 | T4: 30294 | U4: 30537 | V4: 30720 | W4: 30904 | X4: 31059
A5: Annual Growth | C5: 0.024002356 | D5: 0.016997412 | E5: 0.013998473 | F5: 0.012020303 | G5: 0.010003583 | H5: 0.007994543 | I5: 0.0059821888 | J5: 0.0060004305 | K5: 0.0050017386 | L5: 0.011333447 | N5: Annual Growth | P5: 0.024013967 | Q5: 0.017014022 | R5: 0.013992473 | S5: 0.012011201 | T5: 0.0099683281 | U5: 0.0080213904 | V5: 0.0059927301 | W5: 0.0059895833 | X5: 0.005015532 | Y5: 0.01133547
A7: Utah State University | B7: 30373.586 | C7: 31309.782 | D7: 32278.745 | E7: 33281.622 | F7: 34319.599 | G7: 35393.905 | H7: 36505.812 | I7: 37656.636 | J7: 38847.739 | K7: 40080.531 | N7: Utah State University | O7: 22159 | P7: 22916 | Q7: 23674 | R7: 24431 | S7: 25189 | T7: 25947 | U7: 26704 | V7: 27462 | W7: 28220 | X7: 28977
A8: Annual Growth | C8: 0.030822702 | D8: 0.030947608 | E8: 0.031069255 | F8: 0.0311877 | G8: 0.031303001 | H8: 0.031415216 | I8: 0.031524402 | J8: 0.03163062 | K8: 0.031733928 | L8: 0.031292715 | N8: Annual Growth | P8: 0.034162191 | Q8: 0.033077326 | R8: 0.031976007 | S8: 0.031026155 | T8: 0.030092501 | U8: 0.029174856 | V8: 0.028385261 | W8: 0.027601777 | X8: 0.026824947 | Y8: 0.030257891
A10: Weber State University | B10: 26484.841 | C10: 27559.463 | D10: 28671.697 | E10: 29822.858 | F10: 31014.311 | G10: 32247.464 | H10: 33523.778 | I10: 34844.762 | J10: 36211.982 | K10: 37626.814 | N10: Weber State University | O10: 16572.64 | P10: 17281.769 | Q10: 18015.717 | R10: 18775.354 | S10: 19561.578 | T10: 20375.32 | U10: 21217.543 | V10: 22089.243 | W10: 22991.453 | X10: 23925.083
A11: Annual Growth | C11: 0.040574979 | D11: 0.040357595 | E11: 0.040149763 | F11: 0.039950982 | G11: 0.039760784 | H11: 0.03957873 | I11: 0.039404409 | J11: 0.039237436 | K11: 0.039070837 | L11: 0.039787279 | N11: Annual Growth | P11: 0.04278914 | Q11: 0.042469526 | R11: 0.042165222 | S11: 0.041875323 | T11: 0.041598988 | U11: 0.04133544 | V11: 0.041083957 | W11: 0.040843868 | X11: 0.040607678 | Y11: 0.041641016
A13: Southern Utah University | B13: 8881.702 | C13: 9032.5227 | D13: 9240.7725 | E13: 9437.1787 | F13: 9543.1334 | G13: 9680.1559 | H13: 9858.5923 | I13: 10057.169 | J13: 10220.39 | K13: 10431.9 | N13: Southern Utah University | O13: 6720.8 | P13: 6903.1 | Q13: 7046.3 | R13: 7208.1 | S13: 7456.4 | T13: 7666.1 | U13: 7846.1 | V13: 8003.6 | W13: 8150.1 | X13: 8250.4
A14: Annual Growth | C14: 0.016981048 | D14: 0.02305556 | E14: 0.021254297 | F14: 0.011227373 | G14: 0.014358233 | H14: 0.018433212 | I14: 0.020142547 | J14: 0.016229273 | K14: 0.020694861 | L14: 0.018041823 | N14: Annual Growth | P14: 0.027124747 | Q14: 0.020744303 | R14: 0.022962406 | S14: 0.034447358 | T14: 0.028123491 | U14: 0.023479996 | V14: 0.020073667 | W14: 0.018304263 | X14: 0.012306597 | Y14: 0.023062981
A16: Snow College | B16: 4610 | C16: 4796 | D16: 5008 | E16: 5249 | F16: 5523 | G16: 5834 | H16: 6186 | I16: 6584 | J16: 7033 | K16: 7539 | N16: Snow College | O16: 3641.9 | P16: 3823.7 | Q16: 4032 | R16: 4269.7 | S16: 4540.5 | T16: 4848.4 | U16: 5198.1 | V16: 5594.6 | W16: 6043.7 | X16: 6552.1
A17: Annual Growth | C17: 0.040347072 | D17: 0.044203503 | E17: 0.048123003 | F17: 0.052200419 | G17: 0.056309976 | H17: 0.060335962 | I17: 0.06433883 | J17: 0.068195626 | K17: 0.071946538 | L17: 0.056222325 | N17: Annual Growth | P17: 0.049918998 | Q17: 0.054476031 | R17: 0.058953373 | S17: 0.06342366 | T17: 0.067811915 | U17: 0.072126887 | V17: 0.076277871 | W17: 0.080273835 | X17: 0.084120655 | Y17: 0.067487025
A19: Dixie State College | B19: 9211.28 | C19: 9598.1538 | D19: 10001.276 | E19: 10421.33 | F19: 10859.026 | G19: 11315.105 | H19: 11790.339 | I19: 12285.533 | J19: 12801.526 | K19: 13339.19 | N19: Dixie State College | O19: 6798.979 | P19: 7104.9331 | Q19: 7424.655 | R19: 7758.7645 | S19: 8107.9089 | T19: 8472.7648 | U19: 8854.0392 | V19: 9252.471 | W19: 9668.8322 | X19: 10103.93
A20: Annual Growth | C20: 0.042 | D20: 0.042 | E20: 0.042 | F20: 0.042 | G20: 0.042 | H20: 0.042 | I20: 0.042 | J20: 0.042 | K20: 0.042 | L20: 0.042 | N20: Annual Growth | P20: 0.045 | Q20: 0.045 | R20: 0.045 | S20: 0.045 | T20: 0.045 | U20: 0.045 | V20: 0.045 | W20: 0.045 | X20: 0.045 | Y20: 0.045
A22: Utah Valley University | B22: 34085.135 | C22: 35442.53 | D22: 36853.425 | E22: 38280.151 | F22: 39765.144 | G22: 41310.95 | H22: 42920.225 | I22: 44595.744 | J22: 46340.405 | K22: 47870.5 | N22: Utah Valley University | O22: 23636.265 | P22: 24924.223 | Q22: 26084.63 | R22: 27351.335 | S22: 28691.844 | T22: 30110.742 | U22: 31612.901 | V22: 33203.499 | W22: 34888.037 | X22: 36257.167
A23: Annual Growth | C23: 0.03982368 | D23: 0.039807947 | E23: 0.038713526 | F23: 0.038792788 | G23: 0.038873384 | H23: 0.038955162 | I23: 0.039037979 | J23: 0.039121699 | K23: 0.033018594 | L23: 0.038460529 | N23: Annual Growth | P23: 0.054490791 | Q23: 0.046557392 | R23: 0.048561352 | S23: 0.04901074 | T23: 0.04945301 | U23: 0.049887809 | V23: 0.05031482 | W23: 0.050733759 | X23: 0.039243542 | Y23: 0.048694802
A25: Salt Lake Community College | B25: 36871 | C25: 37679 | D25: 38375 | E25: 39018 | F25: 39641 | G25: 39973 | H25: 40179 | I25: 40339 | J25: 40452 | K25: 40541 | N25: Salt Lake Community College | O25: 18505 | P25: 18863 | Q25: 19173 | R25: 19459 | S25: 19734 | T25: 19883 | U25: 19974 | V25: 20045 | W25: 20095 | X25: 20134
A26: Annual Growth | C26: 0.021914242 | D26: 0.018471828 | E26: 0.0167557 | F26: 0.01596699 | G26: 0.0083751671 | H26: 0.0051534786 | I26: 0.0039821797 | J26: 0.0028012593 | K26: 0.0022001384 | L26: 0.010624554 | N26: Annual Growth | P26: 0.019346123 | Q26: 0.016434289 | R26: 0.01491681 | S26: 0.014132278 | T26: 0.0075504206 | U26: 0.0045767741 | V26: 0.003554621 | W26: 0.0024943876 | X26: 0.0019407813 | Y26: 0.0094384983
A28: USHE Totals | B28: 184472.54 | C28: 190187.45 | D28: 195789.91 | E28: 201366.14 | F28: 206952.21 | G28: 212404.58 | H28: 217906.75 | I28: 223526.85 | J28: 229294.04 | K28: 235002.93 | N28: USHE Totals | O28: 126101.58 | P28: 130557.73 | Q28: 134680.3 | R28: 138892.25 | S28: 143276.23 | T28: 147597.33 | U28: 151943.68 | V28: 156370.41 | W28: 160961.12 | X28: 165258.68
A29: Annual Growth | C29: 0.03097972 | D29: 0.029457586 | E29: 0.02848065 | F29: 0.027740881 | G29: 0.02634602 | H29: 0.025904179 | I29: 0.025791302 | J29: 0.02580091 | K29: 0.024897692 | L29: 0.027266549 | N29: Annual Growth | P29: 0.035337715 | Q29: 0.031576663 | R29: 0.031273698 | S29: 0.031563874 | T29: 0.030159195 | U29: 0.029447391 | V29: 0.029134017 | W29: 0.029357917 | X29: 0.026699349 | Y29: 0.030505535
A31: =A4 -> University of Utah | B31: =B4/O4 -> 1.2097837 | C31: =C4/P4 -> 1.20977 | D31: =D4/Q4 -> 1.2097503 | E31: =E4/R4 -> 1.2097574 | F31: =F4/S4 -> 1.2097683 | G31: =G4/T4 -> 1.2098105 | H31: =H4/U4 -> 1.2097783 | I31: =I4/V4 -> 1.2097656 | ... K31: =K4/X4 -> 1.2097621
A32: =A7 -> Utah State University | B32: =B7/O7 -> 1.3707111 | C32: =C7/P7 -> 1.3662848 | D32: =D7/Q7 -> 1.3634682 | E32: =E7/R7 -> 1.3622701 | F32: =F7/S7 -> 1.3624836 | G32: =G7/T7 -> 1.3640847 | H32: =H7/U7 -> 1.3670541 | I32: =I7/V7 -> 1.371227 | ... K32: =K7/X7 -> 1.3831843
A33: =A10 -> Weber State University | B33: =B10/O10 -> 1.5981064 | C33: =C10/P10 -> 1.5947131 | D33: =D10/Q10 -> 1.5914824 | E33: =E10/R10 -> 1.5884046 | F33: =F10/S10 -> 1.5854708 | G33: =G10/T10 -> 1.5826728 | H33: =H10/U10 -> 1.5800028 | I33: =I10/V10 -> 1.5774539 | ... K33: =K10/X10 -> 1.5726931
A34: =A13 -> Southern Utah University | B34: =B13/O13 -> 1.3215245 | C34: =C13/P13 -> 1.3084734 | D34: =D13/Q13 -> 1.3114361 | E34: =E13/R13 -> 1.3092464 | F34: =F13/S13 -> 1.279858 | G34: =G13/T13 -> 1.2627224 | H34: =H13/U13 -> 1.2564959 | I34: =I13/V13 -> 1.2565807 | ... K34: =K13/X13 -> 1.2644114
A35: =A16 -> Snow College | B35: =B16/O16 -> 1.2658228 | C35: =C16/P16 -> 1.2542825 | D35: =D16/Q16 -> 1.2420635 | E35: =E16/R16 -> 1.2293604 | F35: =F16/S16 -> 1.2163859 | G35: =G16/T16 -> 1.2032836 | H35: =H16/U16 -> 1.1900502 | I35: =I16/V16 -> 1.1768491 | ... K35: =K16/X16 -> 1.1506235
A36: =A19 -> Dixie State College | B36: =B19/O19 -> 1.3548034 | C36: =C19/P19 -> 1.350914 | D36: =D19/Q19 -> 1.3470358 | E36: =E19/R19 -> 1.3431687 | F36: =F19/S19 -> 1.3393127 | G36: =G19/T19 -> 1.3354678 | H36: =H19/U19 -> 1.3316339 | I36: =I19/V19 -> 1.3278111 | ... K36: =K19/X19 -> 1.3201982
A37: =A22 -> Utah Valley University | B37: =B22/O22 -> 1.4420694 | C37: =C22/P22 -> 1.4220114 | D37: =D22/Q22 -> 1.4128406 | E37: =E22/R22 -> 1.3995716 | F37: =F22/S22 -> 1.3859389 | G37: =G22/T22 -> 1.3719672 | H37: =H22/U22 -> 1.3576807 | I37: =I22/V22 -> 1.3431037 | ... K37: =K22/X22 -> 1.3203045
A38: =A25 -> Salt Lake Community College | B38: =B25/O25 -> 1.9924885 | C38: =C25/P25 -> 1.9975083 | D38: =D25/Q25 -> 2.0015125 | E38: =E25/R25 -> 2.005139 | F38: =F25/S25 -> 2.0087666 | G38: =G25/T25 -> 2.0104109 | H38: =H25/U25 -> 2.011565 | I38: =I25/V25 -> 2.0124221 | ... K38: =K25/X25 -> 2.0135592
A41: LDSBC
A42: Year | B42: Headcount | C42: Fall FTE | D42: Prev Control | E42: New Control
A43: 2008 | B43: 1383 | C43: 1173 | D43: 3895.7674 | E43: 1173 | F43: =B43/C43 -> 1.1790281
A45: Westerminster
A46: Year | B46: Headcount | C46: Fall FTE | D46: Prev Control | E46: New Control
A47: 2008 | B47: 2857 | C47: 2601 | D47: 2654.0818 | E47: 2601 | F47: =B47/C47 -> 1.0984237

Sheet calc%concurrent
D1: Control Data
A2: Main Campus | D2: Enrollment
A3: Code | B3: College | C3: Campus | D3: Estimates | E3: total headcount
A4: 2.01 | B4: Dixie State College | C4: St. George | D4: 8082
A5: 3 | B5: LDS Bussiness College | D5: 1799 | E5: =Result!B5 -> 2000 | F5: =1-D5/E5 -> 0.1005
B6: SL Community College | C6: Four Main | D6: 25265 | E6: =SUM(Result!I5:Q5) -> 38334 | F6: =1-D6/E6 -> 0.34092451
A7: 6.01 | B7: Utah State University | C7: Logan | D7: 16472
A8: 7.01 | B8: Utah Valley University | C8: Orem | D8: 23172 | E8: =SUM(Result!T5:V5) -> 31739 | F8: =1-D8/E8 -> 0.26992029
A9: 8 | B9: University of Utah | D9: 30819 | E9: =(Result!D5 + Result!E5) -> 31643 | F9: =1-D9/E9 -> 0.026040514
A10: 9.01 | B10: Weber State University | C10: Ogden | D10: 15191 | E10: =Result!F5 -> 19352 | F10: =1-D10/E10 -> 0.21501654
A11: 9.02 | B11: Weber State University | C11: Davis | D11: 3557 | E11: =SUM(Result!G5:H5) -> 5144 | F11: =1-D11/E11 -> 0.30851477
A12: 10 | B12: Westminster College | D12: 3163 | E12: =Result!C5 -> 3200 | F12: =1-D12/E12 -> 0.0115625
A13: the data from RSG, total is used for expansion without concurrent, etc.

Sheet headcounts
A1: YEAR | B1: WSU | C1: LAGOON | D1: SLCCJ | E1: AIRPORT | F1: UOFU | G1: LDSBC | H1: SLCCSC | I1: WESTMIN | J1: SLCCR | K1: SLCCS | L1: UVU | M1: BYU
A2: 2011 | B2: =VLOOKUP(A2,WSU!$A:$E,3,FALSE) -> 25301 | F2: =VLOOKUP(A2,U!A:C,3,FALSE) -> 31660 | L2: =VLOOKUP(A2,UVU!A:C,2,FALSE) -> 33395
A3: 2012 | B3: =VLOOKUP(A3,WSU!$A:$E,3,FALSE) -> 26532 | F3: =VLOOKUP(A3,U!A:C,3,FALSE) -> 32388 | L3: =VLOOKUP(A3,UVU!A:C,2,FALSE) -> 34085.135
A4: 2013 | B4: =VLOOKUP(A4,WSU!$A:$E,3,FALSE) -> 27559.463 | F4: =VLOOKUP(A4,U!A:C,3,FALSE) -> 34770 | L4: =VLOOKUP(A4,UVU!A:C,2,FALSE) -> 35442.53
A5: 2014 | B5: =VLOOKUP(A5,WSU!$A:$E,3,FALSE) -> 28671.697 | F5: =VLOOKUP(A5,U!A:C,3,FALSE) -> 35361 | L5: =VLOOKUP(A5,UVU!A:C,2,FALSE) -> 36853.425
A6: 2015 | B6: =VLOOKUP(A6,WSU!$A:$E,3,FALSE) -> 29822.858 | F6: =VLOOKUP(A6,U!A:C,3,FALSE) -> 35856 | L6: =VLOOKUP(A6,UVU!A:C,2,FALSE) -> 38280.151
A7: 2016 | B7: =VLOOKUP(A7,WSU!$A:$E,3,FALSE) -> 31014.311 | F7: =VLOOKUP(A7,U!A:C,3,FALSE) -> 36287 | L7: =VLOOKUP(A7,UVU!A:C,2,FALSE) -> 39765.144
A8: 2017 | B8: =VLOOKUP(A8,WSU!$A:$E,3,FALSE) -> 32247.464 | F8: =VLOOKUP(A8,U!A:C,3,FALSE) -> 36650 | L8: =VLOOKUP(A8,UVU!A:C,2,FALSE) -> 41310.95
A9: 2018 | B9: =VLOOKUP(A9,WSU!$A:$E,3,FALSE) -> 33523.778 | F9: =VLOOKUP(A9,U!A:C,3,FALSE) -> 36943 | L9: =VLOOKUP(A9,UVU!A:C,2,FALSE) -> 42920.225
A10: 2019 | B10: =VLOOKUP(A10,WSU!$A:$E,3,FALSE) -> 34844.762 | F10: =VLOOKUP(A10,U!A:C,3,FALSE) -> 37164 | L10: =VLOOKUP(A10,UVU!A:C,2,FALSE) -> 44595.744
A11: 2020 | B11: =VLOOKUP(A11,WSU!$A:$E,3,FALSE) -> 36211.982 | F11: =VLOOKUP(A11,U!A:C,3,FALSE) -> 37387 | L11: =VLOOKUP(A11,UVU!A:C,2,FALSE) -> 46340.405
A12: 2021 | B12: =VLOOKUP(A12,WSU!$A:$E,3,FALSE) -> 37626.814 | F12: =VLOOKUP(A12,U!A:C,3,FALSE) -> 37574 | L12: =VLOOKUP(A12,UVU!A:C,2,FALSE) -> 47870.5
A13: 2022 | B13: =VLOOKUP(A13,WSU!$A:$E,4,FALSE) -> 38340.427 | F13: =VLOOKUP(A13,U!A:E,5,FALSE) -> 37862.155 | L13: =VLOOKUP(A13,UVU!A:C,2,FALSE) -> 46883.983
A14: 2023 | B14: =VLOOKUP(A14,WSU!$A:$E,4,FALSE) -> 39054.04 | F14: =VLOOKUP(A14,U!A:E,5,FALSE) -> 38150.311 | L14: =VLOOKUP(A14,UVU!A:C,2,FALSE) -> 48110.317
A15: 2024 | B15: =VLOOKUP(A15,WSU!$A:$E,4,FALSE) -> 39767.653 | F15: =VLOOKUP(A15,U!A:E,5,FALSE) -> 38438.466 | L15: =VLOOKUP(A15,UVU!A:C,2,FALSE) -> 49336.652
A16: 2025 | B16: =VLOOKUP(A16,WSU!$A:$E,4,FALSE) -> 40481.266 | F16: =VLOOKUP(A16,U!A:E,5,FALSE) -> 38726.622 | L16: =VLOOKUP(A16,UVU!A:C,2,FALSE) -> 50562.986
A17: 2026 | B17: =VLOOKUP(A17,WSU!$A:$E,4,FALSE) -> 41194.879 | F17: =VLOOKUP(A17,U!A:E,5,FALSE) -> 39014.777 | L17: =VLOOKUP(A17,UVU!A:C,2,FALSE) -> 51789.32
A18: 2027 | B18: =VLOOKUP(A18,WSU!$A:$E,4,FALSE) -> 41908.492 | F18: =VLOOKUP(A18,U!A:E,5,FALSE) -> 39302.932 | L18: =VLOOKUP(A18,UVU!A:C,2,FALSE) -> 53015.654
A19: 2028 | B19: =VLOOKUP(A19,WSU!$A:$E,4,FALSE) -> 42622.105 | F19: =VLOOKUP(A19,U!A:E,5,FALSE) -> 39591.088 | L19: =VLOOKUP(A19,UVU!A:C,2,FALSE) -> 54241.989
A20: 2029 | B20: =VLOOKUP(A20,WSU!$A:$E,4,FALSE) -> 43335.718 | F20: =VLOOKUP(A20,U!A:E,5,FALSE) -> 39879.243 | L20: =VLOOKUP(A20,UVU!A:C,2,FALSE) -> 55468.323
A21: 2030 | B21: =VLOOKUP(A21,WSU!$A:$E,4,FALSE) -> 44049.331 | F21: =VLOOKUP(A21,U!A:E,5,FALSE) -> 40167.398 | L21: =VLOOKUP(A21,UVU!A:C,2,FALSE) -> 56694.657
A22: 2031 | B22: =VLOOKUP(A22,WSU!$A:$E,4,FALSE) -> 44762.945 | F22: =VLOOKUP(A22,U!A:E,5,FALSE) -> 40455.554 | L22: =VLOOKUP(A22,UVU!A:C,2,FALSE) -> 57920.991
A23: 2032 | B23: =VLOOKUP(A23,WSU!$A:$E,4,FALSE) -> 45476.558 | F23: =VLOOKUP(A23,U!A:E,5,FALSE) -> 40743.709 | L23: =VLOOKUP(A23,UVU!A:C,2,FALSE) -> 59147.326
A24: 2033 | B24: =VLOOKUP(A24,WSU!$A:$E,4,FALSE) -> 46190.171 | F24: =VLOOKUP(A24,U!A:E,5,FALSE) -> 41031.865 | L24: =VLOOKUP(A24,UVU!A:C,2,FALSE) -> 60373.66
... A31: 2040 | B31: =VLOOKUP(A31,WSU!$A:$E,4,FALSE) -> 51185.462 | F31: =VLOOKUP(A31,U!A:E,5,FALSE) -> 43048.952 | L31: =VLOOKUP(A31,UVU!A:C,2,FALSE) -> 68958

Sheet U
A1: Year | B1: Headcount | C1: HC | F1: HC_2019 | J1: U_ss1213A03b | K1: 1970-1971 | L1: 609 | M1: 0.029 | N1: 21795
A2: 1970 | C2: =N1 -> 21795 | F2: =C2 -> 21795 | K2: 1971-1972 | L2: 733 | M2: 0.034 | N2: 23270
A3: 1971 | C3: =N2 -> 23270 | F3: =C3 -> 23270 | K3: 1972-1973 | L3: 840 | M3: 0.04 | N3: 22985
A4: 1972 | C4: =N3 -> 22985 | F4: =C4 -> 22985 | K4: 1973-1974 | L4: 851 | M4: 0.04 | N4: 22919
A5: 1973 | C5: =N4 -> 22919 | F5: =C5 -> 22919 | K5: 1974-1975 | L5: 1005 | M5: 0.046 | N5: 23384
A6: 1974 | C6: =N5 -> 23384 | F6: =C6 -> 23384 | K6: 1975-1976 | L6: 1068 | M6: 0.047 | N6: 24312
A7: 1975 | C7: =N6 -> 24312 | F7: =C7 -> 24312 | K7: 1976-1977 | L7: 988 | M7: 0.046 | N7: 23115
A8: 1976 | C8: =N7 -> 23115 | F8: =C8 -> 23115 | K8: 1977-1978 | L8: 990 | M8: 0.045 | N8: 23034
A9: 1977 | C9: =N8 -> 23034 | F9: =C9 -> 23034 | K9: 1978-1979 | L9: 977 | M9: 0.046 | N9: 21975
A10: 1978 | C10: =N9 -> 21975 | F10: =C10 -> 21975 | K10: 1979-1980 | L10: 1005 | M10: 0.046 | N10: 22175
A11: 1979 | C11: =N10 -> 22175 | F11: =C11 -> 22175 | K11: 1980-1981 | L11: 1124 | M11: 0.049 | N11: 23208
A12: 1980 | C12: =N11 -> 23208 | F12: =C12 -> 23208 | K12: 1981-1982 | L12: 1103 | M12: 0.047 | N12: 23683
A13: 1981 | C13: =N12 -> 23683 | F13: =C13 -> 23683 | K13: 1982-1983 | L13: 1212 | M13: 0.05 | N13: 24793
... A19: 1987 | C19: =N18 -> 24124 | F19: =C19 -> 24124 | K19: 1988-1989 | L19: 1224 | M19: 0.052 | N19: 23626
A20: 1988 | B20: 24052 | C20: =N19 -> 23626 | F20: =C20 -> 23626 | G20: Tab-C-Enrollments | H20: tble3 | I20: table 7 | K20: 1989-1990 | L20: 1314 | M20: 0.056 | N20: 23543
